Workbook

Sheet Cover
A2: INTEGRATION TEST REPORT DOCUMENT
A4: Project Name | B4: Clinic Management System | C4: Created By | D4: QA Team
A5: Project Code | B5: CLINIC | C5: Issue Date | D5: 46246
A6: Document Code | B6: CLINIC_INTEGRATION_TEST | C6: Version | D6: 1.0
A7: Test Environment | B7: Spring Boot; PostgreSQL; Redis; Postman/Swagger | C7: Status | D7: Ready for review
A9: Record of Change
A10: Effective Date | B10: Version | C10: Change Item | D10: A/D/M | E10: Change Description | F10: Reference
A11: 46246 | B11: 1.0 | C11: Initial creation | D11: A | E11: Full integration test design by system flow | F11: Clinic Management System source code

Sheet Test Cases
A2: INTEGRATION TEST FLOW LIST
A4: Project Name | B4: Clinic Management System
A5: Project Code | B5: CLINIC
A6: Number of flows | B6: 15
A7: Number of test cases | B7: 90
A10: No | B10: Flow Name | C10: Flow Code | D10: Sheet Name | E10: Test Requirement | F10: Pre-condition
A11: 1 | B11: Registration and OTP verification | C11: IT01 | D11: IT01-RegisterOTP | E11: Redis OTP -> Account -> Customer Profile -> JWT | F11: Application, PostgreSQL, and Redis are running
A12: 2 | B12: Login and token refresh | C12: IT02 | D12: IT02-LoginToken | E12: Account -> Authentication -> Access Token -> Refresh Token | F12: Application, PostgreSQL, and Redis are running
A13: 3 | B13: Customer profile and insurance lookup | C13: IT03 | D13: IT03-Profile | E13: Account -> Profile -> BHXH insurance service | F13: Application, PostgreSQL, and Redis are running
A14: 4 | B14: Appointment booking and check-in | C14: IT04 | D14: IT04-Appointment | E14: Profile -> Medical Service -> Appointment -> Customer Visit | F14: Application, PostgreSQL, and Redis are running
A15: 5 | B15: Invoice payment and queue creation | C15: IT05 | D15: IT05-PaymentQueue | E15: Invoice -> Transaction -> Queue Ticket | F15: Application, PostgreSQL, and Redis are running
A16: 6 | B16: Queue calling and examination start | C16: IT06 | D16: IT06-QueueExam | E16: Queue Ticket -> Customer Visit -> Vital Signs -> Medical Record | F16: Application, PostgreSQL, and Redis are running
A17: 7 | B17: Diagnosis and prescription | C17: IT07 | D17: IT07-Examination | E17: Medical Record -> ICD-10 -> Prescription -> Medicine | F17: Application, PostgreSQL, and Redis are running
A18: 8 | B18: Clinical test ordering | C18: IT08 | D18: IT08-TestOrder | E18: Medical Record -> Test Request -> Laboratory Queue | F18: Application, PostgreSQL, and Redis are running
A19: 9 | B19: Laboratory result completion | C19: IT09 | D19: IT09-LabResult | E19: Test Request -> Test Result -> Queue Return -> Patient Journey | F19: Application, PostgreSQL, and Redis are running
A20: 10 | B20: Examination completion and follow-up | C20: IT10 | D20: IT10-CompleteFollowup | E20: Medical Record -> Visit -> Queue -> Follow-up Appointment | F20: Application, PostgreSQL, and Redis are running
A21: 11 | B21: Insurance claim and patient payment | C21: IT11 | D21: IT11-InsuranceTxn | E21: BHXH -> Invoice -> Insurance Coverage -> Transaction | F21: Application, PostgreSQL, and Redis are running
A22: 12 | B22: Staff scheduling and attendance | C22: IT12 | D22: IT12-StaffSchedule | E22: Staff -> Capability -> Schedule -> Attendance | F22: Application, PostgreSQL, and Redis are running
... A25: 15 | B25: Patient journey, report, and feedback | C25: IT15 | D25: IT15-JourneyReport | E25: Visit -> Queue -> Medical Record -> Invoice -> Dashboard Report | F25: Application, PostgreSQL, and Redis are running

Sheet Test Statistics
A2: TEST STATISTICS
A5: No | B5: Flow | C5: Passed | D5: Failed | E5: Pending | F5: N/A | G5: Total | H5: Completion
A6: 1 | B6: IT01 - Registration and OTP verification | C6: ='IT01-RegisterOTP'!B6 -> 6 | D6: ='IT01-RegisterOTP'!C6 -> 0 | E6: ='IT01-RegisterOTP'!D6 -> 0 | F6: ='IT01-RegisterOTP'!E6 -> 0 | G6: =SUM(C6:F6) -> 6 | H6: =IF(G6=0,0,(C6+D6+F6)/G6) -> 1
A7: 2 | B7: IT02 - Login and token refresh | C7: ='IT02-LoginToken'!B6 -> 5 | D7: ='IT02-LoginToken'!C6 -> 0 | E7: ='IT02-LoginToken'!D6 -> 0 | F7: ='IT02-LoginToken'!E6 -> 1 | G7: =SUM(C7:F7) -> 6 | H7: =IF(G7=0,0,(C7+D7+F7)/G7) -> 1
A8: 3 | B8: IT03 - Customer profile and insurance lookup | C8: ='IT03-Profile'!B6 -> 6 | D8: ='IT03-Profile'!C6 -> 0 | E8: ='IT03-Profile'!D6 -> 0 | F8: ='IT03-Profile'!E6 -> 0 | G8: =SUM(C8:F8) -> 6 | H8: =IF(G8=0,0,(C8+D8+F8)/G8) -> 1
A9: 4 | B9: IT04 - Appointment booking and check-in | C9: ='IT04-Appointment'!B6 -> 5 | D9: ='IT04-Appointment'!C6 -> 0 | E9: ='IT04-Appointment'!D6 -> 0 | F9: ='IT04-Appointment'!E6 -> 1 | G9: =SUM(C9:F9) -> 6 | H9: =IF(G9=0,0,(C9+D9+F9)/G9) -> 1
A10: 5 | B10: IT05 - Invoice payment and queue creation | C10: ='IT05-PaymentQueue'!B6 -> 6 | D10: ='IT05-PaymentQueue'!C6 -> 0 | E10: ='IT05-PaymentQueue'!D6 -> 0 | F10: ='IT05-PaymentQueue'!E6 -> 0 | G10: =SUM(C10:F10) -> 6 | H10: =IF(G10=0,0,(C10+D10+F10)/G10) -> 1
A11: 6 | B11: IT06 - Queue calling and examination start | C11: ='IT06-QueueExam'!B6 -> 6 | D11: ='IT06-QueueExam'!C6 -> 0 | E11: ='IT06-QueueExam'!D6 -> 0 | F11: ='IT06-QueueExam'!E6 -> 0 | G11: =SUM(C11:F11) -> 6 | H11: =IF(G11=0,0,(C11+D11+F11)/G11) -> 1
A12: 7 | B12: IT07 - Diagnosis and prescription | C12: ='IT07-Examination'!B6 -> 6 | D12: ='IT07-Examination'!C6 -> 0 | E12: ='IT07-Examination'!D6 -> 0 | F12: ='IT07-Examination'!E6 -> 0 | G12: =SUM(C12:F12) -> 6 | H12: =IF(G12=0,0,(C12+D12+F12)/G12) -> 1
A13: 8 | B13: IT08 - Clinical test ordering | C13: ='IT08-TestOrder'!B6 -> 6 | D13: ='IT08-TestOrder'!C6 -> 0 | E13: ='IT08-TestOrder'!D6 -> 0 | F13: ='IT08-TestOrder'!E6 -> 0 | G13: =SUM(C13:F13) -> 6 | H13: =IF(G13=0,0,(C13+D13+F13)/G13) -> 1
A14: 9 | B14: IT09 - Laboratory result completion | C14: ='IT09-LabResult'!B6 -> 6 | D14: ='IT09-LabResult'!C6 -> 0 | E14: ='IT09-LabResult'!D6 -> 0 | F14: ='IT09-LabResult'!E6 -> 0 | G14: =SUM(C14:F14) -> 6 | H14: =IF(G14=0,0,(C14+D14+F14)/G14) -> 1
A15: 10 | B15: IT10 - Examination completion and follow-up | C15: ='IT10-CompleteFollowup'!B6 -> 6 | D15: ='IT10-CompleteFollowup'!C6 -> 0 | E15: ='IT10-CompleteFollowup'!D6 -> 0 | F15: ='IT10-CompleteFollowup'!E6 -> 0 | G15: =SUM(C15:F15) -> 6 | H15: =IF(G15=0,0,(C15+D15+F15)/G15) -> 1
A16: 11 | B16: IT11 - Insurance claim and patient payment | C16: ='IT11-InsuranceTxn'!B6 -> 6 | D16: ='IT11-InsuranceTxn'!C6 -> 0 | E16: ='IT11-InsuranceTxn'!D6 -> 0 | F16: ='IT11-InsuranceTxn'!E6 -> 0 | G16: =SUM(C16:F16) -> 6 | H16: =IF(G16=0,0,(C16+D16+F16)/G16) -> 1
A17: 12 | B17: IT12 - Staff scheduling and attendance | C17: ='IT12-StaffSchedule'!B6 -> 6 | D17: ='IT12-StaffSchedule'!C6 -> 0 | E17: ='IT12-StaffSchedule'!D6 -> 0 | F17: ='IT12-StaffSchedule'!E6 -> 0 | G17: =SUM(C17:F17) -> 6 | H17: =IF(G17=0,0,(C17+D17+F17)/G17) -> 1
A18: 13 | B18: IT13 - Administrative catalog management | C18: ='IT13-AdminCatalog'!B6 -> 6 | D18: ='IT13-AdminCatalog'!C6 -> 0 | E18: ='IT13-AdminCatalog'!D6 -> 0 | F18: ='IT13-AdminCatalog'!E6 -> 0 | G18: =SUM(C18:F18) -> 6 | H18: =IF(G18=0,0,(C18+D18+F18)/G18) -> 1
A19: 14 | B19: IT14 - Notification and support chat | C19: ='IT14-NotifyChat'!B6 -> 6 | D19: ='IT14-NotifyChat'!C6 -> 0 | E19: ='IT14-NotifyChat'!D6 -> 0 | F19: ='IT14-NotifyChat'!E6 -> 0 | G19: =SUM(C19:F19) -> 6 | H19: =IF(G19=0,0,(C19+D19+F19)/G19) -> 1
A20: 15 | B20: IT15 - Patient journey, report, and feedback | C20: ='IT15-JourneyReport'!B6 -> 0 | D20: ='IT15-JourneyReport'!C6 -> 0 | E20: ='IT15-JourneyReport'!D6 -> 6 | F20: ='IT15-JourneyReport'!E6 -> 0 | G20: =SUM(C20:F20) -> 6 | H20: =IF(G20=0,0,(C20+D20+F20)/G20) -> 0

Sheet IT01-RegisterOTP
A2: Feature | B2: IT01 - Registration and OTP verification
A3: Test requirement | B3: Redis OTP -> Account -> Customer Profile -> JWT
A4: Number of TCs | B4: 6
A5: Testing Round | B5: Passed | C5: Failed | D5: Pending | E5: N/A
A6: Round 1 | B6: =COUNTIF(F12:F19,"Passed") -> 6 | C6: =COUNTIF(F12:F19,"Failed") -> 0 | D6: =COUNTIF(F12:F19,"Pending") -> 0 | E6: =COUNTIF(F12:F19,"N/A") -> 0
A7: Round 2 | B7: =COUNTIF(I12:I19,"Passed") -> 0 | C7: =COUNTIF(I12:I19,"Failed") -> 0 | D7: =COUNTIF(I12:I19,"Pending") -> 6 | E7: =COUNTIF(I12:I19,"N/A") -> 0
A8: Round 3 | B8: =COUNTIF(L12:L19,"Passed") -> 0 | C8: =COUNTIF(L12:L19,"Failed") -> 0 | D8: =COUNTIF(L12:L19,"Pending") -> 6 | E8: =COUNTIF(L12:L19,"N/A") -> 0
A10: Test Case ID | B10: Test Case Description | C10: Test Case Procedure | D10: Expected Results | E10: Pre-conditions | F10: Round 1 | G10: Test date | H10: Tester | I10: Round 2 | J10: Test date | K10: Tester | L10: Round 3 | M10: Test date | N10: Tester | O10: Note
A11: Successful flow
A12: IT01-001 | B12: Complete registration and otp verification | C12: 1. Prepare phone = "0944433222"; otp = "482615"; password = "Clinic@123" 2. Send POST /api/auth/register 3. Query the related database records | D12: 1. HTTP status = 200 or 201 2. Account and Profile records are created or updated once 3. Response IDs match the stored records | E12: 1. Database and Redis are available 2. systemRole = "CUSTOMER" 3. Referenced records exist | F12: Passed | G12: 46246 | I12: Pending | L12: Pending | O12: Flow IT01
A13: IT01-002 | B13: Read the integrated result after processing | C13: 1. Complete case IT01-001 2. Call the corresponding GET endpoint 3. Compare response data with the database | D13: 1. HTTP status = 200 2. Response contains the new integrated data 3. No duplicate related record exists | E13: 1. IT01-001 completed successfully 2. Bearer access token is valid | F13: Passed | G13: 46246 | I13: Pending | L13: Pending | O13: Flow IT01
A14: Validation and authorization
A15: IT01-003 | B15: Reject invalid request data | C15: 1. Prepare otp = "48261" 2. Send POST /api/auth/register 3. Check response and database | D15: 1. HTTP status = 400 or 404 2. A validation or not-found error is returned 3. No related record is created or changed | E15: 1. Application and database are available 2. Remaining referenced records are valid | F15: Passed | G15: 46246 | I15: Pending | L15: Pending | O15: Flow IT01
A16: IT01-004 | B16: Reject a protected request without authorization | C16: 1. Set Authorization = null 2. Send GET /api/auth/me 3. Check response and business records | D16: 1. HTTP status = 401 2. The protected operation is rejected 3. Business records remain unchanged | E16: 1. The selected endpoint requires authentication 2. Security context has no authenticated account | F16: Passed | G16: 46246 | I16: Pending | L16: Pending | O16: Flow IT01
A17: State and integration integrity
A18: IT01-005 | B18: Reject an invalid business state | C18: 1. Prepare redis.otpVerified["0944433222"] = false 2. Send POST /api/auth/register 3. Check all participating entities | D18: 1. HTTP status = 400 or 409 2. The current state is preserved 3. No partial downstream update is committed | E18: 1. redis.otpVerified["0944433222"] = false 2. Authentication context satisfies the endpoint requirement | F18: Passed | G18: 46246 | I18: Pending | L18: Pending | O18: Flow IT01
A19: IT01-006 | B19: Prevent duplicate or downstream-inconsistent processing | C19: 1. Prepare account.phone.count = 1 2. Prepare Redis connection = unavailable 3. Send POST /api/auth/register 4. Check transaction rollback and record counts | D19: 1. HTTP status = 400, 409, or 503 2. Existing records remain unchanged 3. No duplicate or orphan record is stored | E19: 1. account.phone.count = 1 2. Redis connection = unavailable 3. Database transaction management is enabled | F19: Passed | G19: 46246 | I19: Pending | L19: Pending | O19: Flow IT01

Sheet IT02-LoginToken
A2: Feature | B2: IT02 - Login and token refresh
A3: Test requirement | B3: Account -> Authentication -> Access Token -> Refresh Token
A4: Number of TCs | B4: 6
A5: Testing Round | B5: Passed | C5: Failed | D5: Pending | E5: N/A
A6: Round 1 | B6: =COUNTIF(F12:F19,"Passed") -> 5 | C6: =COUNTIF(F12:F19,"Failed") -> 0 | D6: =COUNTIF(F12:F19,"Pending") -> 0 | E6: =COUNTIF(F12:F19,"N/A") -> 1
A7: Round 2 | B7: =COUNTIF(I12:I19,"Passed") -> 0 | C7: =COUNTIF(I12:I19,"Failed") -> 0 | D7: =COUNTIF(I12:I19,"Pending") -> 6 | E7: =COUNTIF(I12:I19,"N/A") -> 0
A8: Round 3 | B8: =COUNTIF(L12:L19,"Passed") -> 0 | C8: =COUNTIF(L12:L19,"Failed") -> 0 | D8: =COUNTIF(L12:L19,"Pending") -> 6 | E8: =COUNTIF(L12:L19,"N/A") -> 0
A10: Test Case ID | B10: Test Case Description | C10: Test Case Procedure | D10: Expected Results | E10: Pre-conditions | F10: Round 1 | G10: Test date | H10: Tester | I10: Round 2 | J10: Test date | K10: Tester | L10: Round 3 | M10: Test date | N10: Tester | O10: Note
A11: Successful flow
A12: IT02-001 | B12: Complete login and token refresh | C12: 1. Prepare phone = "0944433222"; password = "Clinic@123" 2. Send POST /api/auth/login 3. Query the related database records | D12: 1. HTTP status = 200 or 201 2. JWT token pair records are created or updated once 3. Response IDs match the stored records | E12: 1. Database and Redis are available 2. systemRole = "CUSTOMER" 3. Referenced records exist | F12: Passed | I12: Pending | L12: Pending | O12: Flow IT02
A13: IT02-002 | B13: Read the integrated result after processing | C13: 1. Complete case IT02-001 2. Call the corresponding GET endpoint 3. Compare response data with the database | D13: 1. HTTP status = 200 2. Response contains the new integrated data 3. No duplicate related record exists | E13: 1. IT02-001 completed successfully 2. Bearer access token is valid | F13: N/A | I13: Pending | L13: Pending | O13: Flow IT02
A14: Validation and authorization
A15: IT02-003 | B15: Reject invalid request data | C15: 1. Prepare password = "Wrong@123" 2. Send POST /api/auth/login 3. Check response and database | D15: 1. HTTP status = 400 or 404 2. A validation or not-found error is returned 3. No related record is created or changed | E15: 1. Application and database are available 2. Remaining referenced records are valid | F15: Passed | I15: Pending | L15: Pending | O15: Flow IT02
A16: IT02-004 | B16: Reject a protected request without authorization | C16: 1. Set Authorization = null 2. Send GET /api/auth/me 3. Check response and business records | D16: 1. HTTP status = 401 2. The protected operation is rejected 3. Business records remain unchanged | E16: 1. The selected endpoint requires authentication 2. Security context has no authenticated account | F16: Passed | I16: Pending | L16: Pending | O16: Flow IT02
A17: State and integration integrity
A18: IT02-005 | B18: Reject an invalid business state | C18: 1. Prepare account.isActive = false 2. Send POST /api/auth/login 3. Check all participating entities | D18: 1. HTTP status = 400 or 409 2. The current state is preserved 3. No partial downstream update is committed | E18: 1. account.isActive = false 2. Authentication context satisfies the endpoint requirement | F18: Passed | I18: Pending | L18: Pending | O18: Flow IT02
A19: IT02-006 | B19: Prevent duplicate or downstream-inconsistent processing | C19: 1. Prepare refreshToken.revoked = true 2. Prepare token.expiresAt = "2026-08-11T10:00:00" 3. Send POST /api/auth/login 4. Check transaction rollback and record counts | D19: 1. HTTP status = 400, 409, or 503 2. Existing records remain unchanged 3. No duplicate or orphan record is stored | E19: 1. refreshToken.revoked = true 2. token.expiresAt = "2026-08-11T10:00:00" 3. Database transaction management is enabled | F19: Passed | I19: Pending | L19: Pending | O19: Flow IT02

Sheet IT03-Profile
A2: Feature | B2: IT03 - Customer profile and insurance lookup
A3: Test requirement | B3: Account -> Profile -> BHXH insurance service
A4: Number of TCs | B4: 6
A5: Testing Round | B5: Passed | C5: Failed | D5: Pending | E5: N/A
A6: Round 1 | B6: =COUNTIF(F12:F19,"Passed") -> 6 | C6: =COUNTIF(F12:F19,"Failed") -> 0 | D6: =COUNTIF(F12:F19,"Pending") -> 0 | E6: =COUNTIF(F12:F19,"N/A") -> 0
A7: Round 2 | B7: =COUNTIF(I12:I19,"Passed") -> 0 | C7: =COUNTIF(I12:I19,"Failed") -> 0 | D7: =COUNTIF(I12:I19,"Pending") -> 6 | E7: =COUNTIF(I12:I19,"N/A") -> 0
A8: Round 3 | B8: =COUNTIF(L12:L19,"Passed") -> 0 | C8: =COUNTIF(L12:L19,"Failed") -> 0 | D8: =COUNTIF(L12:L19,"Pending") -> 6 | E8: =COUNTIF(L12:L19,"N/A") -> 0
A10: Test Case ID | B10: Test Case Description | C10: Test Case Procedure | D10: Expected Results | E10: Pre-conditions | F10: Round 1 | G10: Test date | H10: Tester | I10: Round 2 | J10: Test date | K10: Tester | L10: Round 3 | M10: Test date | N10: Tester | O10: Note
A11: Successful flow
A12: IT03-001 | B12: Complete customer profile and insurance lookup | C12: 1. Prepare fullName = "John Carter"; phone = "0944433222"; insuranceCode = "BH1234567890123" 2. Send PUT /api/v1/profiles/me 3. Query the related database records | D12: 1. HTTP status = 200 or 201 2. Customer Profile records are created or updated once 3. Response IDs match the stored records | E12: 1. Database and Redis are available 2. systemRole = "CUSTOMER" 3. Referenced records exist | F12: Passed | I12: Pending | L12: Pending | O12: Flow IT03
A13: IT03-002 | B13: Read the integrated result after processing | C13: 1. Complete case IT03-001 2. Call the corresponding GET endpoint 3. Compare response data with the database | D13: 1. HTTP status = 200 2. Response contains the new integrated data 3. No duplicate related record exists | E13: 1. IT03-001 completed successfully 2. Bearer access token is valid | F13: Passed | I13: Pending | L13: Pending | O13: Flow IT03
A14: Validation and authorization
A15: IT03-003 | B15: Reject invalid request data | C15: 1. Prepare phone = "123" 2. Send PUT /api/v1/profiles/me 3. Check response and database | D15: 1. HTTP status = 400 or 404 2. A validation or not-found error is returned 3. No related record is created or changed | E15: 1. Application and database are available 2. Remaining referenced records are valid | F15: Passed | I15: Pending | L15: Pending | O15: Flow IT03
A16: IT03-004 | B16: Reject a protected request without authorization | C16: 1. Set Authorization = null 2. Send GET /api/auth/me 3. Check response and business records | D16: 1. HTTP status = 401 2. The protected operation is rejected 3. Business records remain unchanged | E16: 1. The selected endpoint requires authentication 2. Security context has no authenticated account | F16: Passed | I16: Pending | L16: Pending | O16: Flow IT03
A17: State and integration integrity
A18: IT03-005 | B18: Reject an invalid business state | C18: 1. Prepare profile.accountId = "ACC-2002" 2. Send PUT /api/v1/profiles/me 3. Check all participating entities | D18: 1. HTTP status = 400 or 409 2. The current state is preserved 3. No partial downstream update is committed | E18: 1. profile.accountId = "ACC-2002" 2. Authentication context satisfies the endpoint requirement | F18: Passed | I18: Pending | L18: Pending | O18: Flow IT03
A19: IT03-006 | B19: Prevent duplicate or downstream-inconsistent processing | C19: 1. Prepare email = "john.carter@example.com" already exists 2. Prepare BHXH service = timeout 3. Send PUT /api/v1/profiles/me 4. Check transaction rollback and record counts | D19: 1. HTTP status = 400, 409, or 503 2. Existing records remain unchanged 3. No duplicate or orphan record is stored | E19: 1. email = "john.carter@example.com" already exists 2. BHXH service = timeout 3. Database transaction management is enabled | F19: Passed | I19: Pending | L19: Pending | O19: Flow IT03

Sheet IT04-Appointment
A2: Feature | B2: IT04 - Appointment booking and check-in
A3: Test requirement | B3: Profile -> Medical Service -> Appointment -> Customer Visit
A4: Number of TCs | B4: 6
A5: Testing Round | B5: Passed | C5: Failed | D5: Pending | E5: N/A
A6: Round 1 | B6: =COUNTIF(F12:F19,"Passed") -> 5 | C6: =COUNTIF(F12:F19,"Failed") -> 0 | D6: =COUNTIF(F12:F19,"Pending") -> 0 | E6: =COUNTIF(F12:F19,"N/A") -> 1
A7: Round 2 | B7: =COUNTIF(I12:I19,"Passed") -> 0 | C7: =COUNTIF(I12:I19,"Failed") -> 0 | D7: =COUNTIF(I12:I19,"Pending") -> 6 | E7: =COUNTIF(I12:I19,"N/A") -> 0
A8: Round 3 | B8: =COUNTIF(L12:L19,"Passed") -> 0 | C8: =COUNTIF(L12:L19,"Failed") -> 0 | D8: =COUNTIF(L12:L19,"Pending") -> 6 | E8: =COUNTIF(L12:L19,"N/A") -> 0
A10: Test Case ID | B10: Test Case Description | C10: Test Case Procedure | D10: Expected Results | E10: Pre-conditions | F10: Round 1 | G10: Test date | H10: Tester | I10: Round 2 | J10: Test date | K10: Tester | L10: Round 3 | M10: Test date | N10: Tester | O10: Note
A11: Successful flow
A12: IT04-001 | B12: Complete appointment booking and check-in | C12: 1. Prepare customerId = "CUS-1001"; serviceId = "SRV-GENERAL-01"; scheduledAt = "2026-08-13T09:00:00" 2. Send POST /api/v1/appointments 3. Query the related database records | D12: 1. HTTP status = 200 or 201 2. Appointment and CustomerVisit records are created or updated once 3. Response IDs match the stored records | E12: 1. Database and Redis are available 2. systemRole = "RECEPTIONIST" 3. Referenced records exist | F12: Passed | I12: Pending | L12: Pending | O12: Flow IT04
A13: IT04-002 | B13: Read the integrated result after processing | C13: 1. Complete case IT04-001 2. Call the corresponding GET endpoint 3. Compare response data with the database | D13: 1. HTTP status = 200 2. Response contains the new integrated data 3. No duplicate related record exists | E13: 1. IT04-001 completed successfully 2. Bearer access token is valid | F13: Passed | I13: Pending | L13: Pending | O13: Flow IT04
A14: Validation and authorization
A15: IT04-003 | B15: Reject invalid request data | C15: 1. Prepare serviceId = "SRV-UNKNOWN" 2. Send POST /api/v1/appointments 3. Check response and database | D15: 1. HTTP status = 400 or 404 2. A validation or not-found error is returned 3. No related record is created or changed | E15: 1. Application and database are available 2. Remaining referenced records are valid | F15: Passed | I15: Pending | L15: Pending | O15: Flow IT04
A16: IT04-004 | B16: Reject a protected request without authorization | C16: 1. Set Authorization = null 2. Send POST /api/v1/appointments 3. Check response and business records | D16: 1. HTTP status = 401 2. The protected operation is rejected 3. Business records remain unchanged | E16: 1. The selected endpoint requires authentication 2. Security context has no authenticated account | F16: Passed | I16: Pending | L16: Pending | O16: Flow IT04
A17: State and integration integrity
A18: IT04-005 | B18: Reject an invalid business state | C18: 1. Prepare appointment.status = "CANCELLED" 2. Send POST /api/v1/appointments 3. Check all participating entities | D18: 1. HTTP status = 400 or 409 2. The current state is preserved 3. No partial downstream update is committed | E18: 1. appointment.status = "CANCELLED" 2. Authentication context satisfies the endpoint requirement | F18: N/A | I18: Pending | L18: Pending | O18: Flow IT04
A19: IT04-006 | B19: Prevent duplicate or downstream-inconsistent processing | C19: 1. Prepare same customer and scheduledAt count = 1 2. Prepare availableSlot.count = 0 3. Send POST /api/v1/appointments 4. Check transaction rollback and record counts | D19: 1. HTTP status = 400, 409, or 503 2. Existing records remain unchanged 3. No duplicate or orphan record is stored | E19: 1. same customer and scheduledAt count = 1 2. availableSlot.count = 0 3. Database transaction management is enabled | F19: Passed | I19: Pending | L19: Pending | O19: Flow IT04

Sheet IT05-PaymentQueue
A2: Feature | B2: IT05 - Invoice payment and queue creation
A3: Test requirement | B3: Invoice -> Transaction -> Queue Ticket
A4: Number of TCs | B4: 6
A5: Testing Round | B5: Passed | C5: Failed | D5: Pending | E5: N/A
A6: Round 1 | B6: =COUNTIF(F12:F19,"Passed") -> 6 | C6: =COUNTIF(F12:F19,"Failed") -> 0 | D6: =COUNTIF(F12:F19,"Pending") -> 0 | E6: =COUNTIF(F12:F19,"N/A") -> 0
A7: Round 2 | B7: =COUNTIF(I12:I19,"Passed") -> 0 | C7: =COUNTIF(I12:I19,"Failed") -> 0 | D7: =COUNTIF(I12:I19,"Pending") -> 6 | E7: =COUNTIF(I12:I19,"N/A") -> 0
A8: Round 3 | B8: =COUNTIF(L12:L19,"Passed") -> 0 | C8: =COUNTIF(L12:L19,"Failed") -> 0 | D8: =COUNTIF(L12:L19,"Pending") -> 6 | E8: =COUNTIF(L12:L19,"N/A") -> 0
A10: Test Case ID | B10: Test Case Description | C10: Test Case Procedure | D10: Expected Results | E10: Pre-conditions | F10: Round 1 | G10: Test date | H10: Tester | I10: Round 2 | J10: Test date | K10: Tester | L10: Round 3 | M10: Test date | N10: Tester | O10: Note
A11: Successful flow
A12: IT05-001 | B12: Complete invoice payment and queue creation | C12: 1. Prepare invoiceId = "INV-1001"; amount = 500000; paymentMethod = "CASH" 2. Send POST /api/v1/invoices/INV-1001/pay 3. Query the related database records | D12: 1. HTTP status = 200 or 201 2. Transaction and QueueTicket records are created or updated once 3. Response IDs match the stored records | E12: 1. Database and Redis are available 2. systemRole = "RECEPTIONIST" 3. Referenced records exist | F12: Passed | I12: Pending | L12: Pending | O12: Flow IT05
A13: IT05-002 | B13: Read the integrated result after processing | C13: 1. Complete case IT05-001 2. Call the corresponding GET endpoint 3. Compare response data with the database | D13: 1. HTTP status = 200 2. Response contains the new integrated data 3. No duplicate related record exists | E13: 1. IT05-001 completed successfully 2. Bearer access token is valid | F13: Passed | I13: Pending | L13: Pending | O13: Flow IT05
A14: Validation and authorization
A15: IT05-003 | B15: Reject invalid request data | C15: 1. Prepare amount = 499999 2. Send POST /api/v1/invoices/INV-1001/pay 3. Check response and database | D15: 1. HTTP status = 400 or 404 2. A validation or not-found error is returned 3. No related record is created or changed | E15: 1. Application and database are available 2. Remaining referenced records are valid | F15: Passed | I15: Pending | L15: Pending | O15: Flow IT05
A16: IT05-004 | B16: Reject a protected request without authorization | C16: 1. Set Authorization = null 2. Send POST /api/v1/invoices/INV-1001/pay 3. Check response and business records | D16: 1. HTTP status = 401 2. The protected operation is rejected 3. Business records remain unchanged | E16: 1. The selected endpoint requires authentication 2. Security context has no authenticated account | F16: Passed | I16: Pending | L16: Pending | O16: Flow IT05
A17: State and integration integrity
A18: IT05-005 | B18: Reject an invalid business state | C18: 1. Prepare invoice.status = "PAID" 2. Send POST /api/v1/invoices/INV-1001/pay 3. Check all participating entities | D18: 1. HTTP status = 400 or 409 2. The current state is preserved 3. No partial downstream update is committed | E18: 1. invoice.status = "PAID" 2. Authentication context satisfies the endpoint requirement | F18: Passed | I18: Pending | L18: Pending | O18: Flow IT05
A19: IT05-006 | B19: Prevent duplicate or downstream-inconsistent processing | C19: 1. Prepare successfulTransaction.count = 1 2. Prepare invoiceItem.count = 0 3. Send POST /api/v1/invoices/INV-1001/pay 4. Check transaction rollback and record counts | D19: 1. HTTP status = 400, 409, or 503 2. Existing records remain unchanged 3. No duplicate or orphan record is stored | E19: 1. successfulTransaction.count = 1 2. invoiceItem.count = 0 3. Database transaction management is enabled | F19: Passed | I19: Pending | L19: Pending | O19: Flow IT05

Sheet IT06-QueueExam
A2: Feature | B2: IT06 - Queue calling and examination start
A3: Test requirement | B3: Queue Ticket -> Customer Visit -> Vital Signs -> Medical Record
A4: Number of TCs | B4: 6
A5: Testing Round | B5: Passed | C5: Failed | D5: Pending | E5: N/A
A6: Round 1 | B6: =COUNTIF(F12:F19,"Passed") -> 6 | C6: =COUNTIF(F12:F19,"Failed") -> 0 | D6: =COUNTIF(F12:F19,"Pending") -> 0 | E6: =COUNTIF(F12:F19,"N/A") -> 0
A7: Round 2 | B7: =COUNTIF(I12:I19,"Passed") -> 0 | C7: =COUNTIF(I12:I19,"Failed") -> 0 | D7: =COUNTIF(I12:I19,"Pending") -> 6 | E7: =COUNTIF(I12:I19,"N/A") -> 0
A8: Round 3 | B8: =COUNTIF(L12:L19,"Passed") -> 0 | C8: =COUNTIF(L12:L19,"Failed") -> 0 | D8: =COUNTIF(L12:L19,"Pending") -> 6 | E8: =COUNTIF(L12:L19,"N/A") -> 0
A10: Test Case ID | B10: Test Case Description | C10: Test Case Procedure | D10: Expected Results | E10: Pre-conditions | F10: Round 1 | G10: Test date | H10: Tester | I10: Round 2 | J10: Test date | K10: Tester | L10: Round 3 | M10: Test date | N10: Tester | O10: Note
A11: Successful flow
A12: IT06-001 | B12: Complete queue calling and examination start | C12: 1. Prepare queueTicketId = "QUE-1001"; departmentId = "DEP-GENERAL" 2. Send POST /api/v1/queue-tickets/QUE-1001/call 3. Query the related database records | D12: 1. HTTP status = 200 or 201 2. QueueTicket and MedicalRecord records are created or updated once 3. Response IDs match the stored records | E12: 1. Database and Redis are available 2. systemRole = "DOCTOR" 3. Referenced records exist | F12: Passed | I12: Pending | L12: Pending | O12: Flow IT06
A13: IT06-002 | B13: Read the integrated result after processing | C13: 1. Complete case IT06-001 2. Call the corresponding GET endpoint 3. Compare response data with the database | D13: 1. HTTP status = 200 2. Response contains the new integrated data 3. No duplicate related record exists | E13: 1. IT06-001 completed successfully 2. Bearer access token is valid | F13: Passed | I13: Pending | L13: Pending | O13: Flow IT06
A14: Validation and authorization
A15: IT06-003 | B15: Reject invalid request data | C15: 1. Prepare queueTicketId = "QUE-9999" 2. Send POST /api/v1/queue-tickets/QUE-1001/call 3. Check response and database | D15: 1. HTTP status = 400 or 404 2. A validation or not-found error is returned 3. No related record is created or changed | E15: 1. Application and database are available 2. Remaining referenced records are valid | F15: Passed | I15: Pending | L15: Pending | O15: Flow IT06
A16: IT06-004 | B16: Reject a protected request without authorization | C16: 1. Set Authorization = null 2. Send POST /api/v1/queue-tickets/QUE-1001/call 3. Check response and business records | D16: 1. HTTP status = 401 2. The protected operation is rejected 3. Business records remain unchanged | E16: 1. The selected endpoint requires authentication 2. Security context has no authenticated account | F16: Passed | I16: Pending | L16: Pending | O16: Flow IT06
A17: State and integration integrity
A18: IT06-005 | B18: Reject an invalid business state | C18: 1. Prepare queueTicket.status = "DONE" 2. Send POST /api/v1/queue-tickets/QUE-1001/call 3. Check all participating entities | D18: 1. HTTP status = 400 or 409 2. The current state is preserved 3. No partial downstream update is committed | E18: 1. queueTicket.status = "DONE" 2. Authentication context satisfies the endpoint requirement | F18: Passed | I18: Pending | L18: Pending | O18: Flow IT06
A19: IT06-006 | B19: Prevent duplicate or downstream-inconsistent processing | C19: 1. Prepare medicalRecord.count = 1 2. Prepare customerVisit.status = "COMPLETED" 3. Send POST /api/v1/queue-tickets/QUE-1001/call 4. Check transaction rollback and record counts | D19: 1. HTTP status = 400, 409, or 503 2. Existing records remain unchanged 3. No duplicate or orphan record is stored | E19: 1. medicalRecord.count = 1 2. customerVisit.status = "COMPLETED" 3. Database transaction management is enabled | F19: Passed | I19: Pending | L19: Pending | O19: Flow IT06

Sheet IT07-Examination
A2: Feature | B2: IT07 - Diagnosis and prescription
A3: Test requirement | B3: Medical Record -> ICD-10 -> Prescription -> Medicine
A4: Number of TCs | B4: 6
A5: Testing Round | B5: Passed | C5: Failed | D5: Pending | E5: N/A
A6: Round 1 | B6: =COUNTIF(F12:F19,"Passed") -> 6 | C6: =COUNTIF(F12:F19,"Failed") -> 0 | D6: =COUNTIF(F12:F19,"Pending") -> 0 | E6: =COUNTIF(F12:F19,"N/A") -> 0
A7: Round 2 | B7: =COUNTIF(I12:I19,"Passed") -> 0 | C7: =COUNTIF(I12:I19,"Failed") -> 0 | D7: =COUNTIF(I12:I19,"Pending") -> 6 | E7: =COUNTIF(I12:I19,"N/A") -> 0
A8: Round 3 | B8: =COUNTIF(L12:L19,"Passed") -> 0 | C8: =COUNTIF(L12:L19,"Failed") -> 0 | D8: =COUNTIF(L12:L19,"Pending") -> 6 | E8: =COUNTIF(L12:L19,"N/A") -> 0
A10: Test Case ID | B10: Test Case Description | C10: Test Case Procedure | D10: Expected Results | E10: Pre-conditions | F10: Round 1 | G10: Test date | H10: Tester | I10: Round 2 | J10: Test date | K10: Tester | L10: Round 3 | M10: Test date | N10: Tester | O10: Note
A11: Successful flow
A12: IT07-001 | B12: Complete diagnosis and prescription | C12: 1. Prepare medicalRecordId = "MR-1001"; icd10Code = "J00"; medicineId = "MED-001"; quantity = 10 2. Send PUT /api/doctor/examinations/MR-1001 3. Query the related database records | D12: 1. HTTP status = 200 or 201 2. MedicalRecord and Prescription records are created or updated once 3. Response IDs match the stored records | E12: 1. Database and Redis are available 2. systemRole = "DOCTOR" 3. Referenced records exist | F12: Passed | I12: Pending | L12: Pending | O12: Flow IT07
A13: IT07-002 | B13: Read the integrated result after processing | C13: 1. Complete case IT07-001 2. Call the corresponding GET endpoint 3. Compare response data with the database | D13: 1. HTTP status = 200 2. Response contains the new integrated data 3. No duplicate related record exists | E13: 1. IT07-001 completed successfully 2. Bearer access token is valid | F13: Passed | I13: Pending | L13: Pending | O13: Flow IT07
A14: Validation and authorization
A15: IT07-003 | B15: Reject invalid request data | C15: 1. Prepare icd10Code = "ZZZ" 2. Send PUT /api/doctor/examinations/MR-1001 3. Check response and database | D15: 1. HTTP status = 400 or 404 2. A validation or not-found error is returned 3. No related record is created or changed | E15: 1. Application and database are available 2. Remaining referenced records are valid | F15: Passed | I15: Pending | L15: Pending | O15: Flow IT07
A16: IT07-004 | B16: Reject a protected request without authorization | C16: 1. Set Authorization = null 2. Send PUT /api/doctor/examinations/MR-1001 3. Check response and business records | D16: 1. HTTP status = 401 2. The protected operation is rejected 3. Business records remain unchanged | E16: 1. The selected endpoint requires authentication 2. Security context has no authenticated account | F16: Passed | I16: Pending | L16: Pending | O16: Flow IT07
A17: State and integration integrity
A18: IT07-005 | B18: Reject an invalid business state | C18: 1. Prepare medicalRecord.status = "COMPLETED" 2. Send PUT /api/doctor/examinations/MR-1001 3. Check all participating entities | D18: 1. HTTP status = 400 or 409 2. The current state is preserved 3. No partial downstream update is committed | E18: 1. medicalRecord.status = "COMPLETED" 2. Authentication context satisfies the endpoint requirement | F18: Passed | I18: Pending | L18: Pending | O18: Flow IT07
A19: IT07-006 | B19: Prevent duplicate or downstream-inconsistent processing | C19: 1. Prepare prescriptionItem medicineId = "MED-001" already exists 2. Prepare medicine.isActive = false 3. Send PUT /api/doctor/examinations/MR-1001 4. Check transaction rollback and record counts | D19: 1. HTTP status = 400, 409, or 503 2. Existing records remain unchanged 3. No duplicate or orphan record is stored | E19: 1. prescriptionItem medicineId = "MED-001" already exists 2. medicine.isActive = false 3. Database transaction management is enabled | F19: Passed | I19: Pending | L19: Pending | O19: Flow IT07

Sheet IT08-TestOrder
A2: Feature | B2: IT08 - Clinical test ordering
A3: Test requirement | B3: Medical Record -> Test Request -> Laboratory Queue
A4: Number of TCs | B4: 6
A5: Testing Round | B5: Passed | C5: Failed | D5: Pending | E5: N/A
A6: Round 1 | B6: =COUNTIF(F12:F19,"Passed") -> 6 | C6: =COUNTIF(F12:F19,"Failed") -> 0 | D6: =COUNTIF(F12:F19,"Pending") -> 0 | E6: =COUNTIF(F12:F19,"N/A") -> 0
A7: Round 2 | B7: =COUNTIF(I12:I19,"Passed") -> 0 | C7: =COUNTIF(I12:I19,"Failed") -> 0 | D7: =COUNTIF(I12:I19,"Pending") -> 6 | E7: =COUNTIF(I12:I19,"N/A") -> 0
A8: Round 3 | B8: =COUNTIF(L12:L19,"Passed") -> 0 | C8: =COUNTIF(L12:L19,"Failed") -> 0 | D8: =COUNTIF(L12:L19,"Pending") -> 6 | E8: =COUNTIF(L12:L19,"N/A") -> 0
A10: Test Case ID | B10: Test Case Description | C10: Test Case Procedure | D10: Expected Results | E10: Pre-conditions | F10: Round 1 | G10: Test date | H10: Tester | I10: Round 2 | J10: Test date | K10: Tester | L10: Round 3 | M10: Test date | N10: Tester | O10: Note
A11: Successful flow
A12: IT08-001 | B12: Complete clinical test ordering | C12: 1. Prepare medicalRecordId = "MR-1001"; serviceId = "SRV-LAB-CBC" 2. Send POST /api/v1/test-requests 3. Query the related database records | D12: 1. HTTP status = 200 or 201 2. TestRequest and QueueTicket records are created or updated once 3. Response IDs match the stored records | E12: 1. Database and Redis are available 2. systemRole = "DOCTOR" 3. Referenced records exist | F12: Passed | I12: Pending | L12: Pending | O12: Flow IT08
A13: IT08-002 | B13: Read the integrated result after processing | C13: 1. Complete case IT08-001 2. Call the corresponding GET endpoint 3. Compare response data with the database | D13: 1. HTTP status = 200 2. Response contains the new integrated data 3. No duplicate related record exists | E13: 1. IT08-001 completed successfully 2. Bearer access token is valid | F13: Passed | I13: Pending | L13: Pending | O13: Flow IT08
A14: Validation and authorization
A15: IT08-003 | B15: Reject invalid request data | C15: 1. Prepare serviceId = "SRV-UNKNOWN" 2. Send POST /api/v1/test-requests 3. Check response and database | D15: 1. HTTP status = 400 or 404 2. A validation or not-found error is returned 3. No related record is created or changed | E15: 1. Application and database are available 2. Remaining referenced records are valid | F15: Passed | I15: Pending | L15: Pending | O15: Flow IT08
A16: IT08-004 | B16: Reject a protected request without authorization | C16: 1. Set Authorization = null 2. Send POST /api/v1/test-requests 3. Check response and business records | D16: 1. HTTP status = 401 2. The protected operation is rejected 3. Business records remain unchanged | E16: 1. The selected endpoint requires authentication 2. Security context has no authenticated account | F16: Passed | I16: Pending | L16: Pending | O16: Flow IT08
A17: State and integration integrity
A18: IT08-005 | B18: Reject an invalid business state | C18: 1. Prepare medicalRecord.status = "COMPLETED" 2. Send POST /api/v1/test-requests 3. Check all participating entities | D18: 1. HTTP status = 400 or 409 2. The current state is preserved 3. No partial downstream update is committed | E18: 1. medicalRecord.status = "COMPLETED" 2. Authentication context satisfies the endpoint requirement | F18: Passed | I18: Pending | L18: Pending | O18: Flow IT08
A19: IT08-006 | B19: Prevent duplicate or downstream-inconsistent processing | C19: 1. Prepare sameServiceRequest.count = 1 2. Prepare laboratoryDepartment.status = "INACTIVE" 3. Send POST /api/v1/test-requests 4. Check transaction rollback and record counts | D19: 1. HTTP status = 400, 409, or 503 2. Existing records remain unchanged 3. No duplicate or orphan record is stored | E19: 1. sameServiceRequest.count = 1 2. laboratoryDepartment.status = "INACTIVE" 3. Database transaction management is enabled | F19: Passed | I19: Pending | L19: Pending | O19: Flow IT08

Sheet IT09-LabResult
A2: Feature | B2: IT09 - Laboratory result completion
A3: Test requirement | B3: Test Request -> Test Result -> Queue Return -> Patient Journey
A4: Number of TCs | B4: 6
A5: Testing Round | B5: Passed | C5: Failed | D5: Pending | E5: N/A
A6: Round 1 | B6: =COUNTIF(F12:F19,"Passed") -> 6 | C6: =COUNTIF(F12:F19,"Failed") -> 0 | D6: =COUNTIF(F12:F19,"Pending") -> 0 | E6: =COUNTIF(F12:F19,"N/A") -> 0
A7: Round 2 | B7: =COUNTIF(I12:I19,"Passed") -> 0 | C7: =COUNTIF(I12:I19,"Failed") -> 0 | D7: =COUNTIF(I12:I19,"Pending") -> 6 | E7: =COUNTIF(I12:I19,"N/A") -> 0
A8: Round 3 | B8: =COUNTIF(L12:L19,"Passed") -> 0 | C8: =COUNTIF(L12:L19,"Failed") -> 0 | D8: =COUNTIF(L12:L19,"Pending") -> 6 | E8: =COUNTIF(L12:L19,"N/A") -> 0
A10: Test Case ID | B10: Test Case Description | C10: Test Case Procedure | D10: Expected Results | E10: Pre-conditions | F10: Round 1 | G10: Test date | H10: Tester | I10: Round 2 | J10: Test date | K10: Tester | L10: Round 3 | M10: Test date | N10: Tester | O10: Note
A11: Successful flow
A12: IT09-001 | B12: Complete laboratory result completion | C12: 1. Prepare testRequestId = "TR-1001"; conclusion = "CBC values within reference range" 2. Send POST /api/v1/test-requests/TR-1001/result/complete 3. Query the related database records | D12: 1. HTTP status = 200 or 201 2. TestResult and QueueTicket records are created or updated once 3. Response IDs match the stored records | E12: 1. Database and Redis are available 2. systemRole = "TECHNICIAN" 3. Referenced records exist | F12: Passed | I12: Pending | L12: Pending | O12: Flow IT09
A13: IT09-002 | B13: Read the integrated result after processing | C13: 1. Complete case IT09-001 2. Call the corresponding GET endpoint 3. Compare response data with the database | D13: 1. HTTP status = 200 2. Response contains the new integrated data 3. No duplicate related record exists | E13: 1. IT09-001 completed successfully 2. Bearer access token is valid | F13: Passed | I13: Pending | L13: Pending | O13: Flow IT09
A14: Validation and authorization
A15: IT09-003 | B15: Reject invalid request data | C15: 1. Prepare testRequestId = "TR-9999" 2. Send POST /api/v1/test-requests/TR-1001/result/complete 3. Check response and database | D15: 1. HTTP status = 400 or 404 2. A validation or not-found error is returned 3. No related record is created or changed | E15: 1. Application and database are available 2. Remaining referenced records are valid | F15: Passed | I15: Pending | L15: Pending | O15: Flow IT09
A16: IT09-004 | B16: Reject a protected request without authorization | C16: 1. Set Authorization = null 2. Send POST /api/v1/test-requests/TR-1001/result/complete 3. Check response and business records | D16: 1. HTTP status = 401 2. The protected operation is rejected 3. Business records remain unchanged | E16: 1. The selected endpoint requires authentication 2. Security context has no authenticated account | F16: Passed | I16: Pending | L16: Pending | O16: Flow IT09
A17: State and integration integrity
A18: IT09-005 | B18: Reject an invalid business state | C18: 1. Prepare testRequest.status = "COMPLETED" 2. Send POST /api/v1/test-requests/TR-1001/result/complete 3. Check all participating entities | D18: 1. HTTP status = 400 or 409 2. The current state is preserved 3. No partial downstream update is committed | E18: 1. testRequest.status = "COMPLETED" 2. Authentication context satisfies the endpoint requirement | F18: Passed | I18: Pending | L18: Pending | O18: Flow IT09
A19: IT09-006 | B19: Prevent duplicate or downstream-inconsistent processing | C19: 1. Prepare completedResult.count = 1 2. Prepare resultFile = "cbc-result.exe" 3. Send POST /api/v1/test-requests/TR-1001/result/complete 4. Check transaction rollback and record counts | D19: 1. HTTP status = 400, 409, or 503 2. Existing records remain unchanged 3. No duplicate or orphan record is stored | E19: 1. completedResult.count = 1 2. resultFile = "cbc-result.exe" 3. Database transaction management is enabled | F19: Passed | I19: Pending | L19: Pending | O19: Flow IT09

Sheet IT10-CompleteFollowup
A2: Feature | B2: IT10 - Examination completion and follow-up
A3: Test requirement | B3: Medical Record -> Visit -> Queue -> Follow-up Appointment
A4: Number of TCs | B4: 6
A5: Testing Round | B5: Passed | C5: Failed | D5: Pending | E5: N/A
A6: Round 1 | B6: =COUNTIF(F12:F19,"Passed") -> 6 | C6: =COUNTIF(F12:F19,"Failed") -> 0 | D6: =COUNTIF(F12:F19,"Pending") -> 0 | E6: =COUNTIF(F12:F19,"N/A") -> 0
A7: Round 2 | B7: =COUNTIF(I12:I19,"Passed") -> 0 | C7: =COUNTIF(I12:I19,"Failed") -> 0 | D7: =COUNTIF(I12:I19,"Pending") -> 6 | E7: =COUNTIF(I12:I19,"N/A") -> 0
A8: Round 3 | B8: =COUNTIF(L12:L19,"Passed") -> 0 | C8: =COUNTIF(L12:L19,"Failed") -> 0 | D8: =COUNTIF(L12:L19,"Pending") -> 6 | E8: =COUNTIF(L12:L19,"N/A") -> 0
A10: Test Case ID | B10: Test Case Description | C10: Test Case Procedure | D10: Expected Results | E10: Pre-conditions | F10: Round 1 | G10: Test date | H10: Tester | I10: Round 2 | J10: Test date | K10: Tester | L10: Round 3 | M10: Test date | N10: Tester | O10: Note
A11: Successful flow
A12: IT10-001 | B12: Complete examination completion and follow-up | C12: 1. Prepare medicalRecordId = "MR-1001"; followUpDate = "2026-08-20" 2. Send POST /api/v1/medical-records/MR-1001/complete 3. Query the related database records | D12: 1. HTTP status = 200 or 201 2. MedicalRecord, Visit, and Follow-up records are created or updated once 3. Response IDs match the stored records | E12: 1. Database and Redis are available 2. systemRole = "DOCTOR" 3. Referenced records exist | F12: Passed | I12: Pending | L12: Pending | O12: Flow IT10
A13: IT10-002 | B13: Read the integrated result after processing | C13: 1. Complete case IT10-001 2. Call the corresponding GET endpoint 3. Compare response data with the database | D13: 1. HTTP status = 200 2. Response contains the new integrated data 3. No duplicate related record exists | E13: 1. IT10-001 completed successfully 2. Bearer access token is valid | F13: Passed | I13: Pending | L13: Pending | O13: Flow IT10
A14: Validation and authorization
A15: IT10-003 | B15: Reject invalid request data | C15: 1. Prepare followUpDate = "2026-08-10" 2. Send POST /api/v1/medical-records/MR-1001/complete 3. Check response and database | D15: 1. HTTP status = 400 or 404 2. A validation or not-found error is returned 3. No related record is created or changed | E15: 1. Application and database are available 2. Remaining referenced records are valid | F15: Passed | I15: Pending | L15: Pending | O15: Flow IT10
A16: IT10-004 | B16: Reject a protected request without authorization | C16: 1. Set Authorization = null 2. Send POST /api/v1/medical-records/MR-1001/complete 3. Check response and business records | D16: 1. HTTP status = 401 2. The protected operation is rejected 3. Business records remain unchanged | E16: 1. The selected endpoint requires authentication 2. Security context has no authenticated account | F16: Passed | I16: Pending | L16: Pending | O16: Flow IT10
A17: State and integration integrity
A18: IT10-005 | B18: Reject an invalid business state | C18: 1. Prepare incompleteTestRequest.count = 1 2. Send POST /api/v1/medical-records/MR-1001/complete 3. Check all participating entities | D18: 1. HTTP status = 400 or 409 2. The current state is preserved 3. No partial downstream update is committed | E18: 1. incompleteTestRequest.count = 1 2. Authentication context satisfies the endpoint requirement | F18: Passed | I18: Pending | L18: Pending | O18: Flow IT10
A19: IT10-006 | B19: Prevent duplicate or downstream-inconsistent processing | C19: 1. Prepare medicalRecord.status = "COMPLETED" 2. Prepare customerVisit.status = "CANCELLED" 3. Send POST /api/v1/medical-records/MR-1001/complete 4. Check transaction rollback and record counts | D19: 1. HTTP status = 400, 409, or 503 2. Existing records remain unchanged 3. No duplicate or orphan record is stored | E19: 1. medicalRecord.status = "COMPLETED" 2. customerVisit.status = "CANCELLED" 3. Database transaction management is enabled | F19: Passed | I19: Pending | L19: Pending | O19: Flow IT10

Sheet IT11-InsuranceTxn
A2: Feature | B2: IT11 - Insurance claim and patient payment
A3: Test requirement | B3: BHXH -> Invoice -> Insurance Coverage -> Transaction
A4: Number of TCs | B4: 6
A5: Testing Round | B5: Passed | C5: Failed | D5: Pending | E5: N/A
A6: Round 1 | B6: =COUNTIF(F12:F19,"Passed") -> 6 | C6: =COUNTIF(F12:F19,"Failed") -> 0 | D6: =COUNTIF(F12:F19,"Pending") -> 0 | E6: =COUNTIF(F12:F19,"N/A") -> 0
A7: Round 2 | B7: =COUNTIF(I12:I19,"Passed") -> 0 | C7: =COUNTIF(I12:I19,"Failed") -> 0 | D7: =COUNTIF(I12:I19,"Pending") -> 6 | E7: =COUNTIF(I12:I19,"N/A") -> 0
A8: Round 3 | B8: =COUNTIF(L12:L19,"Passed") -> 0 | C8: =COUNTIF(L12:L19,"Failed") -> 0 | D8: =COUNTIF(L12:L19,"Pending") -> 6 | E8: =COUNTIF(L12:L19,"N/A") -> 0
A10: Test Case ID | B10: Test Case Description | C10: Test Case Procedure | D10: Expected Results | E10: Pre-conditions | F10: Round 1 | G10: Test date | H10: Tester | I10: Round 2 | J10: Test date | K10: Tester | L10: Round 3 | M10: Test date | N10: Tester | O10: Note
A11: Successful flow
A12: IT11-001 | B12: Complete insurance claim and patient payment | C12: 1. Prepare insuranceCode = "BH1234567890123"; invoiceId = "INV-1001"; coveredAmount = 400000 2. Send POST /api/v1/invoices/INV-1001/insurance 3. Query the related database records | D12: 1. HTTP status = 200 or 201 2. Invoice and Insurance Claim records are created or updated once 3. Response IDs match the stored records | E12: 1. Database and Redis are available 2. systemRole = "RECEPTIONIST" 3. Referenced records exist | F12: Passed | I12: Pending | L12: Pending | O12: Flow IT11
A13: IT11-002 | B13: Read the integrated result after processing | C13: 1. Complete case IT11-001 2. Call the corresponding GET endpoint 3. Compare response data with the database | D13: 1. HTTP status = 200 2. Response contains the new integrated data 3. No duplicate related record exists | E13: 1. IT11-001 completed successfully 2. Bearer access token is valid | F13: Passed | I13: Pending | L13: Pending | O13: Flow IT11
A14: Validation and authorization
A15: IT11-003 | B15: Reject invalid request data | C15: 1. Prepare insuranceCode = "BH0000000000000" 2. Send POST /api/v1/invoices/INV-1001/insurance 3. Check response and database | D15: 1. HTTP status = 400 or 404 2. A validation or not-found error is returned 3. No related record is created or changed | E15: 1. Application and database are available 2. Remaining referenced records are valid | F15: Passed | I15: Pending | L15: Pending | O15: Flow IT11
A16: IT11-004 | B16: Reject a protected request without authorization | C16: 1. Set Authorization = null 2. Send POST /api/v1/invoices/INV-1001/insurance 3. Check response and business records | D16: 1. HTTP status = 401 2. The protected operation is rejected 3. Business records remain unchanged | E16: 1. The selected endpoint requires authentication 2. Security context has no authenticated account | F16: Passed | I16: Pending | L16: Pending | O16: Flow IT11
A17: State and integration integrity
A18: IT11-005 | B18: Reject an invalid business state | C18: 1. Prepare insurance.status = "EXPIRED" 2. Send POST /api/v1/invoices/INV-1001/insurance 3. Check all participating entities | D18: 1. HTTP status = 400 or 409 2. The current state is preserved 3. No partial downstream update is committed | E18: 1. insurance.status = "EXPIRED" 2. Authentication context satisfies the endpoint requirement | F18: Passed | I18: Pending | L18: Pending | O18: Flow IT11
A19: IT11-006 | B19: Prevent duplicate or downstream-inconsistent processing | C19: 1. Prepare insuranceClaim.count = 1 2. Prepare BHXH response.status = "UNAVAILABLE" 3. Send POST /api/v1/invoices/INV-1001/insurance 4. Check transaction rollback and record counts | D19: 1. HTTP status = 400, 409, or 503 2. Existing records remain unchanged 3. No duplicate or orphan record is stored | E19: 1. insuranceClaim.count = 1 2. BHXH response.status = "UNAVAILABLE" 3. Database transaction management is enabled | F19: Passed | I19: Pending | L19: Pending | O19: Flow IT11

Sheet IT12-StaffSchedule
A2: Feature | B2: IT12 - Staff scheduling and attendance
A3: Test requirement | B3: Staff -> Capability -> Schedule -> Attendance
A4: Number of TCs | B4: 6
A5: Testing Round | B5: Passed | C5: Failed | D5: Pending | E5: N/A
A6: Round 1 | B6: =COUNTIF(F12:F19,"Passed") -> 6 | C6: =COUNTIF(F12:F19,"Failed") -> 0 | D6: =COUNTIF(F12:F19,"Pending") -> 0 | E6: =COUNTIF(F12:F19,"N/A") -> 0
A7: Round 2 | B7: =COUNTIF(I12:I19,"Passed") -> 0 | C7: =COUNTIF(I12:I19,"Failed") -> 0 | D7: =COUNTIF(I12:I19,"Pending") -> 6 | E7: =COUNTIF(I12:I19,"N/A") -> 0
A8: Round 3 | B8: =COUNTIF(L12:L19,"Passed") -> 0 | C8: =COUNTIF(L12:L19,"Failed") -> 0 | D8: =COUNTIF(L12:L19,"Pending") -> 6 | E8: =COUNTIF(L12:L19,"N/A") -> 0
A10: Test Case ID | B10: Test Case Description | C10: Test Case Procedure | D10: Expected Results | E10: Pre-conditions | F10: Round 1 | G10: Test date | H10: Tester | I10: Round 2 | J10: Test date | K10: Tester | L10: Round 3 | M10: Test date | N10: Tester | O10: Note
A11: Successful flow
A12: IT12-001 | B12: Complete staff scheduling and attendance | C12: 1. Prepare staffId = "STF-DOC-01"; startAt = "2026-08-13T08:00:00"; endAt = "2026-08-13T12:00:00" 2. Send POST /api/v1/schedules 3. Query the related database records | D12: 1. HTTP status = 200 or 201 2. StaffSchedule and Attendance records are created or updated once 3. Response IDs match the stored records | E12: 1. Database and Redis are available 2. systemRole = "CLINIC_MANAGER" 3. Referenced records exist | F12: Passed | I12: Pending | L12: Pending | O12: Flow IT12
A13: IT12-002 | B13: Read the integrated result after processing | C13: 1. Complete case IT12-001 2. Call the corresponding GET endpoint 3. Compare response data with the database | D13: 1. HTTP status = 200 2. Response contains the new integrated data 3. No duplicate related record exists | E13: 1. IT12-001 completed successfully 2. Bearer access token is valid | F13: Passed | I13: Pending | L13: Pending | O13: Flow IT12
A14: Validation and authorization
A15: IT12-003 | B15: Reject invalid request data | C15: 1. Prepare endAt = "2026-08-13T07:00:00" 2. Send POST /api/v1/schedules 3. Check response and database | D15: 1. HTTP status = 400 or 404 2. A validation or not-found error is returned 3. No related record is created or changed | E15: 1. Application and database are available 2. Remaining referenced records are valid | F15: Passed | I15: Pending | L15: Pending | O15: Flow IT12
A16: IT12-004 | B16: Reject a protected request without authorization | C16: 1. Set Authorization = null 2. Send POST /api/v1/schedules 3. Check response and business records | D16: 1. HTTP status = 401 2. The protected operation is rejected 3. Business records remain unchanged | E16: 1. The selected endpoint requires authentication 2. Security context has no authenticated account | F16: Passed | I16: Pending | L16: Pending | O16: Flow IT12
A17: State and integration integrity
A18: IT12-005 | B18: Reject an invalid business state | C18: 1. Prepare staff.isActive = false 2. Send POST /api/v1/schedules 3. Check all participating entities | D18: 1. HTTP status = 400 or 409 2. The current state is preserved 3. No partial downstream update is committed | E18: 1. staff.isActive = false 2. Authentication context satisfies the endpoint requirement | F18: Passed | I18: Pending | L18: Pending | O18: Flow IT12
A19: IT12-006 | B19: Prevent duplicate or downstream-inconsistent processing | C19: 1. Prepare overlappingSchedule.count = 1 2. Prepare capability.serviceId = "SRV-GENERAL-01" not found 3. Send POST /api/v1/schedules 4. Check transaction rollback and record counts | D19: 1. HTTP status = 400, 409, or 503 2. Existing records remain unchanged 3. No duplicate or orphan record is stored | E19: 1. overlappingSchedule.count = 1 2. capability.serviceId = "SRV-GENERAL-01" not found 3. Database transaction management is enabled | F19: Passed | I19: Pending | L19: Pending | O19: Flow IT12

Sheet IT13-AdminCatalog
A2: Feature | B2: IT13 - Administrative catalog management
A3: Test requirement | B3: Department -> Medical Service -> Service Capability
A4: Number of TCs | B4: 6
A5: Testing Round | B5: Passed | C5: Failed | D5: Pending | E5: N/A
A6: Round 1 | B6: =COUNTIF(F12:F19,"Passed") -> 6 | C6: =COUNTIF(F12:F19,"Failed") -> 0 | D6: =COUNTIF(F12:F19,"Pending") -> 0 | E6: =COUNTIF(F12:F19,"N/A") -> 0
A7: Round 2 | B7: =COUNTIF(I12:I19,"Passed") -> 0 | C7: =COUNTIF(I12:I19,"Failed") -> 0 | D7: =COUNTIF(I12:I19,"Pending") -> 6 | E7: =COUNTIF(I12:I19,"N/A") -> 0
A8: Round 3 | B8: =COUNTIF(L12:L19,"Passed") -> 0 | C8: =COUNTIF(L12:L19,"Failed") -> 0 | D8: =COUNTIF(L12:L19,"Pending") -> 6 | E8: =COUNTIF(L12:L19,"N/A") -> 0
A10: Test Case ID | B10: Test Case Description | C10: Test Case Procedure | D10: Expected Results | E10: Pre-conditions | F10: Round 1 | G10: Test date | H10: Tester | I10: Round 2 | J10: Test date | K10: Tester | L10: Round 3 | M10: Test date | N10: Tester | O10: Note
A11: Successful flow
A12: IT13-001 | B12: Complete administrative catalog management | C12: 1. Prepare serviceCode = "SRV-CARDIO-01"; serviceName = "Cardiology Consultation"; price = 500000 2. Send POST /api/v1/medical-services 3. Query the related database records | D12: 1. HTTP status = 200 or 201 2. MedicalService and Capability records are created or updated once 3. Response IDs match the stored records | E12: 1. Database and Redis are available 2. systemRole = "ADMIN" 3. Referenced records exist | F12: Passed | I12: Pending | L12: Pending | O12: Flow IT13
A13: IT13-002 | B13: Read the integrated result after processing | C13: 1. Complete case IT13-001 2. Call the corresponding GET endpoint 3. Compare response data with the database | D13: 1. HTTP status = 200 2. Response contains the new integrated data 3. No duplicate related record exists | E13: 1. IT13-001 completed successfully 2. Bearer access token is valid | F13: Passed | I13: Pending | L13: Pending | O13: Flow IT13
A14: Validation and authorization
A15: IT13-003 | B15: Reject invalid request data | C15: 1. Prepare price = -1 2. Send POST /api/v1/medical-services 3. Check response and database | D15: 1. HTTP status = 400 or 404 2. A validation or not-found error is returned 3. No related record is created or changed | E15: 1. Application and database are available 2. Remaining referenced records are valid | F15: Passed | I15: Pending | L15: Pending | O15: Flow IT13
A16: IT13-004 | B16: Reject a protected request without authorization | C16: 1. Set Authorization = null 2. Send POST /api/v1/medical-services 3. Check response and business records | D16: 1. HTTP status = 401 2. The protected operation is rejected 3. Business records remain unchanged | E16: 1. The selected endpoint requires authentication 2. Security context has no authenticated account | F16: Passed | I16: Pending | L16: Pending | O16: Flow IT13
A17: State and integration integrity
A18: IT13-005 | B18: Reject an invalid business state | C18: 1. Prepare department.status = "INACTIVE" 2. Send POST /api/v1/medical-services 3. Check all participating entities | D18: 1. HTTP status = 400 or 409 2. The current state is preserved 3. No partial downstream update is committed | E18: 1. department.status = "INACTIVE" 2. Authentication context satisfies the endpoint requirement | F18: Passed | I18: Pending | L18: Pending | O18: Flow IT13
A19: IT13-006 | B19: Prevent duplicate or downstream-inconsistent processing | C19: 1. Prepare serviceCode = "SRV-CARDIO-01" already exists 2. Prepare serviceCategoryId = "CAT-9999" 3. Send POST /api/v1/medical-services 4. Check transaction rollback and record counts | D19: 1. HTTP status = 400, 409, or 503 2. Existing records remain unchanged 3. No duplicate or orphan record is stored | E19: 1. serviceCode = "SRV-CARDIO-01" already exists 2. serviceCategoryId = "CAT-9999" 3. Database transaction management is enabled | F19: Passed | I19: Pending | L19: Pending | O19: Flow IT13

Sheet IT14-NotifyChat
A2: Feature | B2: IT14 - Notification and support chat
A3: Test requirement | B3: Account -> Notification -> Chat Session -> Message
A4: Number of TCs | B4: 6
A5: Testing Round | B5: Passed | C5: Failed | D5: Pending | E5: N/A
A6: Round 1 | B6: =COUNTIF(F12:F19,"Passed") -> 6 | C6: =COUNTIF(F12:F19,"Failed") -> 0 | D6: =COUNTIF(F12:F19,"Pending") -> 0 | E6: =COUNTIF(F12:F19,"N/A") -> 0
A7: Round 2 | B7: =COUNTIF(I12:I19,"Passed") -> 0 | C7: =COUNTIF(I12:I19,"Failed") -> 0 | D7: =COUNTIF(I12:I19,"Pending") -> 6 | E7: =COUNTIF(I12:I19,"N/A") -> 0
