Workbook

Sheet Cover
B2: TEST REPORT DOCUMENT
A4: Project Name | B4: Clinic Management System | E4: Creator
A5: Project Code | B5: CMS | E5: Issue Date | F5: 2026-08-12
A6: Document Code | B6: =B5&"_IntegrationTest_v1.0" -> CMS_IntegrationTest_v1.0 | E6: Version | F6: v1.0
A9: Record of change
A10: Effective Date | B10: Version | C10: Change Item | D10: *A,D,M | E10: Change description | F10: Reference
A11: 2026-08-12 | B11: v1.0 | C11: Initial sample | D11: A | E11: Full English edition with concrete test data values. | F11: Source code repository

Sheet Test Cases
D1: TEST CASE LIST
B3: Project Name | D3: Clinic Management System
B4: Project Code | D4: CMS
B5: Test Environment Setup Description | D5: Spring Boot API; PostgreSQL; Redis; Postman/Swagger
B8: No | C8: Function Name | D8: Sheet Name | E8: Description | F8: Pre-Condition
B9: 1 | C9: IT01 - Registration and OTP verification | D9: IT01-Register | E9: Registration and OTP verification | F9: See explicit values in the Feature sheet
B10: 2 | C10: IT02 - Login and token refresh | D10: IT02-LoginToken | E10: Login and token refresh | F10: See explicit values in the Feature sheet
B11: 3 | C11: IT03 - Customer profile management | D11: IT03-Profile | E11: Customer profile management | F11: See explicit values in the Feature sheet
B12: 4 | C12: IT04 - Appointment booking and check-in | D12: IT04-Appointment | E12: Appointment booking and check-in | F12: See explicit values in the Feature sheet
B13: 5 | C13: IT05 - Invoice payment and queue creation | D13: IT05-PaymentQueue | E13: Invoice payment and queue creation | F13: See explicit values in the Feature sheet
B14: 6 | C14: IT06 - Queue handling and examination start | D14: IT06-QueueExam | E14: Queue handling and examination start | F14: See explicit values in the Feature sheet
B15: 7 | C15: IT07 - Diagnosis and prescription | D15: IT07-Examination | E15: Diagnosis and prescription | F15: See explicit values in the Feature sheet
B16: 8 | C16: IT08 - Clinical test ordering | D16: IT08-TestOrder | E16: Clinical test ordering | F16: See explicit values in the Feature sheet
B17: 9 | C17: IT09 - Laboratory result completion | D17: IT09-LabResult | E17: Laboratory result completion | F17: See explicit values in the Feature sheet
B18: 10 | C18: IT10 - Examination completion and follow-up | D18: IT10-CompleteFollowup | E18: Examination completion and follow-up | F18: See explicit values in the Feature sheet
B19: 11 | C19: IT11 - Insurance and payment transaction | D19: IT11-InsuranceTxn | E19: Insurance and payment transaction | F19: See explicit values in the Feature sheet
B20: 12 | C20: IT12 - Staff scheduling and attendance | D20: IT12-StaffSchedule | E20: Staff scheduling and attendance | F20: See explicit values in the Feature sheet
... B23: 15 | C23: IT15 - Patient journey, reporting, and feedback | D23: IT15-JourneyReport | E23: Patient journey, reporting, and feedback | F23: See explicit values in the Feature sheet

Sheet Test Statistics
B1: TEST STATISTICS
B3: Project Name | C3: Clinic Management System | E3: Creator
B4: Project Code | C4: CMS | E4: Reviewer/Approver
B5: Document Code | C5: =C4&"_Integration Test Report_v1.0" -> CMS_Integration Test Report_v1.0 | E5: Issue Date | H5: 2026-08-12
B6: Notes | C6: Sample review: IT01, IT04, IT09
B10: No | C10: Module code | D10: Passed | E10: Failed | F10: Pending | G10: N/A | H10: Number of test cases
B11: 1 | C11: ='IT01-Register'!B2 -> IT01 - Registration and OTP verification | D11: ='IT01-Register'!B6 -> 0 | E11: ='IT01-Register'!C6 -> 0 | F11: ='IT01-Register'!D6 -> 6 | G11: ='IT01-Register'!E6 -> 0 | H11: ='IT01-Register'!B4 -> 6
B12: 2 | C12: ='IT02-LoginToken'!B2 -> IT02 - Login and token refresh | D12: ='IT02-LoginToken'!B6 -> 0 | E12: ='IT02-LoginToken'!C6 -> 0 | F12: ='IT02-LoginToken'!D6 -> 6 | G12: ='IT02-LoginToken'!E6 -> 0 | H12: ='IT02-LoginToken'!B4 -> 6
B13: 3 | C13: ='IT03-Profile'!B2 -> IT03 - Customer profile management | D13: ='IT03-Profile'!B6 -> 0 | E13: ='IT03-Profile'!C6 -> 0 | F13: ='IT03-Profile'!D6 -> 6 | G13: ='IT03-Profile'!E6 -> 0 | H13: ='IT03-Profile'!B4 -> 6
B14: 4 | C14: ='IT04-Appointment'!B2 -> IT04 - Appointment booking and check-in | D14: ='IT04-Appointment'!B6 -> 0 | E14: ='IT04-Appointment'!C6 -> 0 | F14: ='IT04-Appointment'!D6 -> 6 | G14: ='IT04-Appointment'!E6 -> 0 | H14: ='IT04-Appointment'!B4 -> 6
B15: 5 | C15: ='IT05-PaymentQueue'!B2 -> IT05 - Invoice payment and queue creation | D15: ='IT05-PaymentQueue'!B6 -> 0 | E15: ='IT05-PaymentQueue'!C6 -> 0 | F15: ='IT05-PaymentQueue'!D6 -> 6 | G15: ='IT05-PaymentQueue'!E6 -> 0 | H15: ='IT05-PaymentQueue'!B4 -> 6
B16: 6 | C16: ='IT06-QueueExam'!B2 -> IT06 - Queue handling and examination start | D16: ='IT06-QueueExam'!B6 -> 0 | E16: ='IT06-QueueExam'!C6 -> 0 | F16: ='IT06-QueueExam'!D6 -> 6 | G16: ='IT06-QueueExam'!E6 -> 0 | H16: ='IT06-QueueExam'!B4 -> 6
B17: 7 | C17: ='IT07-Examination'!B2 -> IT07 - Diagnosis and prescription | D17: ='IT07-Examination'!B6 -> 0 | E17: ='IT07-Examination'!C6 -> 0 | F17: ='IT07-Examination'!D6 -> 6 | G17: ='IT07-Examination'!E6 -> 0 | H17: ='IT07-Examination'!B4 -> 6
B18: 8 | C18: ='IT08-TestOrder'!B2 -> IT08 - Clinical test ordering | D18: ='IT08-TestOrder'!B6 -> 0 | E18: ='IT08-TestOrder'!C6 -> 0 | F18: ='IT08-TestOrder'!D6 -> 6 | G18: ='IT08-TestOrder'!E6 -> 0 | H18: ='IT08-TestOrder'!B4 -> 6
B19: 9 | C19: ='IT09-LabResult'!B2 -> IT09 - Laboratory result completion | D19: ='IT09-LabResult'!B6 -> 0 | E19: ='IT09-LabResult'!C6 -> 0 | F19: ='IT09-LabResult'!D6 -> 6 | G19: ='IT09-LabResult'!E6 -> 0 | H19: ='IT09-LabResult'!B4 -> 6
B20: 10 | C20: ='IT10-CompleteFollowup'!B2 -> IT10 - Examination completion and follow-up | D20: ='IT10-CompleteFollowup'!B6 -> 0 | E20: ='IT10-CompleteFollowup'!C6 -> 0 | F20: ='IT10-CompleteFollowup'!D6 -> 6 | G20: ='IT10-CompleteFollowup'!E6 -> 0 | H20: ='IT10-CompleteFollowup'!B4 -> 6
B21: 11 | C21: ='IT11-InsuranceTxn'!B2 -> IT11 - Insurance and payment transaction | D21: ='IT11-InsuranceTxn'!B6 -> 0 | E21: ='IT11-InsuranceTxn'!C6 -> 0 | F21: ='IT11-InsuranceTxn'!D6 -> 6 | G21: ='IT11-InsuranceTxn'!E6 -> 0 | H21: ='IT11-InsuranceTxn'!B4 -> 6
B22: 12 | C22: ='IT12-StaffSchedule'!B2 -> IT12 - Staff scheduling and attendance | D22: ='IT12-StaffSchedule'!B6 -> 0 | E22: ='IT12-StaffSchedule'!C6 -> 0 | F22: ='IT12-StaffSchedule'!D6 -> 6 | G22: ='IT12-StaffSchedule'!E6 -> 0 | H22: ='IT12-StaffSchedule'!B4 -> 6
B23: 13 | C23: ='IT13-AdminCatalog'!B2 -> IT13 - Administrative catalog management | D23: ='IT13-AdminCatalog'!B6 -> 0 | E23: ='IT13-AdminCatalog'!C6 -> 0 | F23: ='IT13-AdminCatalog'!D6 -> 6 | G23: ='IT13-AdminCatalog'!E6 -> 0 | H23: ='IT13-AdminCatalog'!B4 -> 6
B24: 14 | C24: ='IT14-NotifyChat'!B2 -> IT14 - Notification and support chat | D24: ='IT14-NotifyChat'!B6 -> 0 | E24: ='IT14-NotifyChat'!C6 -> 0 | F24: ='IT14-NotifyChat'!D6 -> 6 | G24: ='IT14-NotifyChat'!E6 -> 0 | H24: ='IT14-NotifyChat'!B4 -> 6
B25: 15 | C25: ='IT15-JourneyReport'!B2 -> IT15 - Patient journey, reporting, and feedback | D25: ='IT15-JourneyReport'!B6 -> 0 | E25: ='IT15-JourneyReport'!C6 -> 0 | F25: ='IT15-JourneyReport'!D6 -> 6 | G25: ='IT15-JourneyReport'!E6 -> 0 | H25: ='IT15-JourneyReport'!B4 -> 6
C27: Sub total | D27: =SUM(D11:D25) -> 0 | E27: =SUM(E11:E25) -> 0 | F27: =SUM(F11:F25) -> 90 | G27: =SUM(G11:G25) -> 0 | H27: =SUM(H11:H25) -> 90
C29: Test coverage | E29: =IFERROR((D27+E27)*100/(H27-G27),0) -> 0 | F29: %
C30: Test successful coverage | E30: =IFERROR(D27*100/(H27-G27),0) -> 0 | F30: %

Sheet IT01-Register
A2: Feature | B2: IT01 - Registration and OTP verification | R2: Passed
A3: Test requirement | B3: Redis OTP -> Account -> Profile -> JWT | R3: Failed
A4: Number of TCs | B4: 6 | R4: Pending
A5: Testing Round | B5: Passed | C5: Failed | D5: Pending | E5: N/A | R5: N/A
A6: Round 1 | B6: =COUNTIF($F$12:$F$1000,B$5) -> 0 | C6: =COUNTIF($F$12:$F$1000,C$5) -> 0 | D6: =COUNTIF($F$12:$F$1000,D$5) -> 6 | E6: =COUNTIF($F$12:$F$1000,E$5) -> 0
A7: Round 2 | B7: =COUNTIF($I$12:$I$1000,B$5) -> 0 | C7: =COUNTIF($I$12:$I$1000,C$5) -> 0 | D7: =COUNTIF($I$12:$I$1000,D$5) -> 6 | E7: =COUNTIF($I$12:$I$1000,E$5) -> 0
A8: Round 3 | B8: =COUNTIF($L$12:$L$1000,B$5) -> 0 | C8: =COUNTIF($L$12:$L$1000,C$5) -> 0 | D8: =COUNTIF($L$12:$L$1000,D$5) -> 6 | E8: =COUNTIF($L$12:$L$1000,E$5) -> 0
A10: Test Case ID | B10: Test Case Description | C10: Test Case Procedure | D10: Expected Results | E10: Pre-conditions | F10: Round 1 | G10: Test date | H10: Tester | I10: Round 2 | J10: Test date | K10: Tester | L10: Round 3 | M10: Test date | N10: Tester | O10: Note
A11: Valid concrete input values
A12: IT01-001 | B12: Register with verified OTP | C12: phone = "0944433222" otp = "482615" password = "Clinic@123" fullName = "John Carter" dateOfBirth = "1998-05-20" POST /api/auth/register | D12: httpStatus = 201 response.accessToken != null account.phone = "0944433222" account.systemRole = "CUSTOMER" profile.fullName = "John Carter" | E12: redis.otp["0944433222"] = "482615" redis.otpVerified["0944433222"] = true account.phone.count = 0 | F12: Pending | I12: Pending | L12: Pending | O12: V1, V2, V3, V4, V5, V6
A13: IT01-002 | B13: Reject five-digit OTP | C13: phone = "0944433222" otp = "48261" POST /api/auth/verify-register-otp | D13: httpStatus = 400 response.code = "INVALID_OTP" redis.otpVerified["0944433222"] = null | E13: redis.otp["0944433222"] = "482615" | F13: Pending | I13: Pending | L13: Pending | O13: B2
A14: Invalid concrete input values
A15: IT01-003 | B15: Reject registration without OTP verification | C15: phone = "0944433222" password = "Clinic@123" POST /api/auth/register | D15: httpStatus = 400 response.code = "OTP_NOT_VERIFIED" account.phone.count = 0 | E15: redis.otpVerified["0944433222"] = null | F15: Pending | I15: Pending | L15: Pending | O15: I2
A16: IT01-004 | B16: Reject short password | C16: phone = "0944433222" password = "abc" POST /api/auth/register | D16: httpStatus = 400 response.code = "VALIDATION_ERROR" account.phone.count = 0 | E16: redis.otpVerified["0944433222"] = true | F16: Pending | I16: Pending | L16: Pending | O16: I3
A17: Boundary and state values
A18: IT01-005 | B18: Reject duplicate phone | C18: phone = "0944433222" password = "Clinic@123" POST /api/auth/register | D18: httpStatus = 409 response.code = "PHONE_ALREADY_EXISTS" account.phone.count = 1 | E18: account.phone = "0944433222" account.phone.count = 1 | F18: Pending | I18: Pending | L18: Pending | O18: I6
A19: IT01-006 | B19: Reject future date of birth | C19: phone = "0988776655" dateOfBirth = "2027-01-01" POST /api/auth/register | D19: httpStatus = 400 response.code = "INVALID_DATE_OF_BIRTH" account.phone.count = 0 | E19: redis.otpVerified["0988776655"] = true | F19: Pending | I19: Pending | L19: Pending | O19: I5

Sheet CA-IT01-Register
A1: Test Condition Analysis
A2: Variable | B2: Valid Partition | C2: Tag | D2: Invalid Partition | E2: Tag | F2: Valid Boundary | G2: Tag | H2: Invalid Boundary | I2: Tag
A3: phone | B3: phone = "0944433222" | C3: V1 | D3: phone = "944433222" | E3: I1 | F3: phone = "0944433222" | G3: B1 | H3: phone = "944433222" | I3: IB1
A4: otp | B4: otp = "482615" | C4: V2 | D4: otp = "48261" | E4: I2 | F4: otp = "482615" | G4: B2 | H4: otp = "48261" | I4: IB2
A5: password | B5: password = "Clinic@123" | C5: V3 | D5: password = "abc" | E5: I3 | F5: password = "Clinic@123" | G5: B3 | H5: password = "abc" | I5: IB3
A6: fullName | B6: fullName = "John Carter" | C6: V4 | D6: fullName = "" | E6: I4 | F6: fullName = "John Carter" | G6: B4 | H6: fullName = "" | I6: IB4
A7: dateOfBirth | B7: dateOfBirth = "1998-05-20" | C7: V5 | D7: dateOfBirth = "2027-01-01" | E7: I5 | F7: dateOfBirth = "1998-05-20" | G7: B5 | H7: dateOfBirth = "2027-01-01" | I7: IB5
A8: phone uniqueness | B8: account.phone.count = 0 | C8: V6 | D8: account.phone.count = 1 | E8: I6 | F8: account.phone.count = 0 | G8: B6 | H8: account.phone.count = 1 | I8: IB6 | K8: TC | L8: VP1, VP2, VP3, VB1, VB3
A27: Notes: | B27: Every partition uses an explicit variable value. Tags are referenced by Test Design and Feature sheets.

Sheet TD-IT01-Register
A1: Test Case Design
A2: Test Case | B2: Description | C2: Expected Outcome | D2: New Tag Covered
A3: 1 | B3: phone = "0944433222" otp = "482615" password = "Clinic@123" fullName = "John Carter" dateOfBirth = "1998-05-20" POST /api/auth/register | C3: httpStatus = 201 response.accessToken != null account.phone = "0944433222" account.systemRole = "CUSTOMER" profile.fullName = "John Carter" | D3: V1, V2, V3, V4, V5, V6
A4: 2 | B4: phone = "0944433222" otp = "48261" POST /api/auth/verify-register-otp | C4: httpStatus = 400 response.code = "INVALID_OTP" redis.otpVerified["0944433222"] = null | D4: B2
A5: 3 | B5: phone = "0944433222" password = "Clinic@123" POST /api/auth/register | C5: httpStatus = 400 response.code = "OTP_NOT_VERIFIED" account.phone.count = 0 | D5: I2
A6: 4 | B6: phone = "0944433222" password = "abc" POST /api/auth/register | C6: httpStatus = 400 response.code = "VALIDATION_ERROR" account.phone.count = 0 | D6: I3
A7: 5 | B7: phone = "0944433222" password = "Clinic@123" POST /api/auth/register | C7: httpStatus = 409 response.code = "PHONE_ALREADY_EXISTS" account.phone.count = 1 | D7: I6
A8: 6 | B8: phone = "0988776655" dateOfBirth = "2027-01-01" POST /api/auth/register | C8: httpStatus = 400 response.code = "INVALID_DATE_OF_BIRTH" account.phone.count = 0 | D8: I5

Sheet IT04-Appointment
A2: Feature | B2: IT04 - Appointment booking and check-in | R2: Passed
A3: Test requirement | B3: Profile -> Appointment -> Visit -> Invoice | R3: Failed
A4: Number of TCs | B4: 6 | R4: Pending
A5: Testing Round | B5: Passed | C5: Failed | D5: Pending | E5: N/A | R5: N/A
A6: Round 1 | B6: =COUNTIF($F$12:$F$1000,B$5) -> 0 | C6: =COUNTIF($F$12:$F$1000,C$5) -> 0 | D6: =COUNTIF($F$12:$F$1000,D$5) -> 6 | E6: =COUNTIF($F$12:$F$1000,E$5) -> 0
A7: Round 2 | B7: =COUNTIF($I$12:$I$1000,B$5) -> 0 | C7: =COUNTIF($I$12:$I$1000,C$5) -> 0 | D7: =COUNTIF($I$12:$I$1000,D$5) -> 6 | E7: =COUNTIF($I$12:$I$1000,E$5) -> 0
A8: Round 3 | B8: =COUNTIF($L$12:$L$1000,B$5) -> 0 | C8: =COUNTIF($L$12:$L$1000,C$5) -> 0 | D8: =COUNTIF($L$12:$L$1000,D$5) -> 6 | E8: =COUNTIF($L$12:$L$1000,E$5) -> 0
A10: Test Case ID | B10: Test Case Description | C10: Test Case Procedure | D10: Expected Results | E10: Pre-conditions | F10: Round 1 | G10: Test date | H10: Tester | I10: Round 2 | J10: Test date | K10: Tester | L10: Round 3 | M10: Test date | N10: Tester | O10: Note
A11: Valid concrete input values
A12: IT04-001 | B12: Create or process appointment booking and check-in | C12: customerId = "CUS-1001" scheduledAt = "2026-08-13T09:00:00" serviceId = "SRV-GENERAL-01" POST /api/v1/appointments | D12: httpStatus = 200 response.flow = "IT04" database.updatedRows = 1 | E12: customerId = "CUS-1001" scheduledAt = "2026-08-13T09:00:00" | F12: Pending | I12: Pending | L12: Pending | O12: V1, V2, V3
A13: IT04-002 | B13: Reject invalid customerId | C13: customerId = "CUS-9999" scheduledAt = "2026-08-13T09:00:00" POST /api/v1/appointments | D13: httpStatus = 404 response.code = "APPOINTMENT_NOT_FOUND" database.updatedRows = 0 | E13: customerId = "CUS-9999" | F13: Pending | I13: Pending | L13: Pending | O13: I1
A14: Invalid concrete input values
A15: IT04-003 | B15: Reject invalid scheduledAt | C15: customerId = "CUS-1001" scheduledAt = "2026-08-11T09:00:00" POST /api/v1/appointments | D15: httpStatus = 400 response.code = "INVALID_SCHEDULEDAT" database.updatedRows = 0 | E15: customerId = "CUS-1001" | F15: Pending | I15: Pending | L15: Pending | O15: I2
A16: IT04-004 | B16: Accept boundary value for appointment status | C16: appointment.status = "PENDING" activeVisit.count = 0 POST /api/v1/appointments | D16: httpStatus = 200 response.appointmentstatus = "\"PENDING\"" database.updatedRows = 1 | E16: customerId = "CUS-1001" | F16: Pending | I16: Pending | L16: Pending | O16: B4, V5
A17: Boundary and state values
A18: IT04-005 | B18: Reject invalid active visit | C18: activeVisit.count = 1 POST /api/v1/appointments | D18: httpStatus = 400 response.code = "INVALID_ACTIVE_VISIT" database.updatedRows = 0 | E18: customerId = "CUS-1001" | F18: Pending | I18: Pending | L18: Pending | O18: I5
A19: IT04-006 | B19: Reject invalid staff role | C19: staff.systemRole = "CUSTOMER" POST /api/v1/appointments | D19: httpStatus = 409 response.code = "INVALID_STAFF_ROLE" database.updatedRows = 0 | E19: staff.systemRole = "CUSTOMER" | F19: Pending | I19: Pending | L19: Pending | O19: I6

Sheet MessageList
A1: Message ID | B1: Description | C1: Note
A2: IT01-INVALID | B2: The submitted variable value is invalid. | C2: IT01
A3: IT01-STATE | B3: The stored entity state does not allow this operation. | C3: IT01
A4: IT02-INVALID | B4: The submitted variable value is invalid. | C4: IT02
A5: IT02-STATE | B5: The stored entity state does not allow this operation. | C5: IT02
A6: IT03-INVALID | B6: The submitted variable value is invalid. | C6: IT03
A7: IT03-STATE | B7: The stored entity state does not allow this operation. | C7: IT03
A8: IT04-INVALID | B8: The submitted variable value is invalid. | C8: IT04
A9: IT04-STATE | B9: The stored entity state does not allow this operation. | C9: IT04
A10: IT05-INVALID | B10: The submitted variable value is invalid. | C10: IT05
A11: IT05-STATE | B11: The stored entity state does not allow this operation. | C11: IT05
A12: IT06-INVALID | B12: The submitted variable value is invalid. | C12: IT06
... A31: IT15-STATE | B31: The stored entity state does not allow this operation. | C31: IT15

Sheet CA-IT04-Appointment
A1: Test Condition Analysis
A2: Variable | B2: Valid Partition | C2: Tag | D2: Invalid Partition | E2: Tag | F2: Valid Boundary | G2: Tag | H2: Invalid Boundary | I2: Tag
A3: customerId | B3: customerId = "CUS-1001" | C3: V1 | D3: customerId = "CUS-9999" | E3: I1 | F3: customerId = "CUS-1001" | G3: B1 | H3: customerId = "CUS-9999" | I3: IB1
A4: scheduledAt | B4: scheduledAt = "2026-08-13T09:00:00" | C4: V2 | D4: scheduledAt = "2026-08-11T09:00:00" | E4: I2 | F4: scheduledAt = "2026-08-13T09:00:00" | G4: B2 | H4: scheduledAt = "2026-08-11T09:00:00" | I4: IB2
A5: serviceId | B5: serviceId = "SRV-GENERAL-01" | C5: V3 | D5: serviceId = "SRV-UNKNOWN" | E5: I3 | F5: serviceId = "SRV-GENERAL-01" | G5: B3 | H5: serviceId = "SRV-UNKNOWN" | I5: IB3
A6: appointment status | B6: appointment.status = "PENDING" | C6: V4 | D6: appointment.status = "CHECKED_IN" | E6: I4 | F6: appointment.status = "PENDING" | G6: B4 | H6: appointment.status = "CHECKED_IN" | I6: IB4
A7: active visit | B7: activeVisit.count = 0 | C7: V5 | D7: activeVisit.count = 1 | E7: I5 | F7: activeVisit.count = 0 | G7: B5 | H7: activeVisit.count = 1 | I7: IB5
A8: staff role | B8: staff.systemRole = "RECEPTIONIST" | C8: V6 | D8: staff.systemRole = "CUSTOMER" | E8: I6 | F8: staff.systemRole = "RECEPTIONIST" | G8: B6 | H8: staff.systemRole = "CUSTOMER" | I8: IB6 | K8: TC | L8: VP1, VP2, VP3, VB1, VB3
A27: Notes: | B27: Every partition uses an explicit variable value. Tags are referenced by Test Design and Feature sheets.

Sheet TD-IT04-Appointment
A1: Test Case Design
A2: Test Case | B2: Description | C2: Expected Outcome | D2: New Tag Covered
A3: 1 | B3: customerId = "CUS-1001" scheduledAt = "2026-08-13T09:00:00" serviceId = "SRV-GENERAL-01" POST /api/v1/appointments | C3: httpStatus = 200 response.flow = "IT04" database.updatedRows = 1 | D3: V1, V2, V3
A4: 2 | B4: customerId = "CUS-9999" scheduledAt = "2026-08-13T09:00:00" POST /api/v1/appointments | C4: httpStatus = 404 response.code = "APPOINTMENT_NOT_FOUND" database.updatedRows = 0 | D4: I1
A5: 3 | B5: customerId = "CUS-1001" scheduledAt = "2026-08-11T09:00:00" POST /api/v1/appointments | C5: httpStatus = 400 response.code = "INVALID_SCHEDULEDAT" database.updatedRows = 0 | D5: I2
A6: 4 | B6: appointment.status = "PENDING" activeVisit.count = 0 POST /api/v1/appointments | C6: httpStatus = 200 response.appointmentstatus = "\"PENDING\"" database.updatedRows = 1 | D6: B4, V5
A7: 5 | B7: activeVisit.count = 1 POST /api/v1/appointments | C7: httpStatus = 400 response.code = "INVALID_ACTIVE_VISIT" database.updatedRows = 0 | D7: I5
A8: 6 | B8: staff.systemRole = "CUSTOMER" POST /api/v1/appointments | C8: httpStatus = 409 response.code = "INVALID_STAFF_ROLE" database.updatedRows = 0 | D8: I6

Sheet CA-IT09-LabResult
A1: Test Condition Analysis
A2: Variable | B2: Valid Partition | C2: Tag | D2: Invalid Partition | E2: Tag | F2: Valid Boundary | G2: Tag | H2: Invalid Boundary | I2: Tag
A3: request status | B3: testRequest.status = "IN_PROGRESS" | C3: V1 | D3: testRequest.status = "COMPLETED" | E3: I1 | F3: testRequest.status = "IN_PROGRESS" | G3: B1 | H3: testRequest.status = "COMPLETED" | I3: IB1
A4: resultFile | B4: resultFile = "cbc-result.pdf" | C4: V2 | D4: resultFile = "cbc-result.jpg" | E4: I2 | F4: resultFile = "cbc-result.pdf" | G4: B2 | H4: resultFile = "cbc-result.jpg" | I4: IB2
A5: fileSize | B5: fileSize = 1048576 | C5: V3 | D5: fileSize = 10485761 | E5: I3 | F5: fileSize = 1048576 | G5: B3 | H5: fileSize = 10485761 | I5: IB3
A6: conclusion | B6: conclusion = "CBC values within reference range" | C6: V4 | D6: conclusion = "" | E6: I4 | F6: conclusion = "CBC values within reference range" | G6: B4 | H6: conclusion = "" | I6: IB4
A7: verifiedBy | B7: verifiedBy = "STF-HEAD-LAB-01" | C7: V5 | D7: verifiedBy = "STF-DOC-01" | E7: I5 | F7: verifiedBy = "STF-HEAD-LAB-01" | G7: B5 | H7: verifiedBy = "STF-DOC-01" | I7: IB5
A8: queue status | B8: queueTicket.status = "IN_PROGRESS" | C8: V6 | D8: queueTicket.status = "WAITING" | E8: I6 | F8: queueTicket.status = "IN_PROGRESS" | G8: B6 | H8: queueTicket.status = "WAITING" | I8: IB6 | K8: TC | L8: VP1, VP2, VP3, VB1, VB3
A27: Notes: | B27: Every partition uses an explicit variable value. Tags are referenced by Test Design and Feature sheets.

Sheet TD-IT09-LabResult
A1: Test Case Design
A2: Test Case | B2: Description | C2: Expected Outcome | D2: New Tag Covered
A3: 1 | B3: testRequest.status = "IN_PROGRESS" resultFile = "cbc-result.pdf" fileSize = 1048576 POST /api/v1/test-requests/TR-1001/result/complete | C3: httpStatus = 200 response.flow = "IT09" database.updatedRows = 1 | D3: V1, V2, V3
A4: 2 | B4: testRequest.status = "COMPLETED" resultFile = "cbc-result.pdf" POST /api/v1/test-requests/TR-1001/result/complete | C4: httpStatus = 404 response.code = "LABRESULT_NOT_FOUND" database.updatedRows = 0 | D4: I1
A5: 3 | B5: testRequest.status = "IN_PROGRESS" resultFile = "cbc-result.jpg" POST /api/v1/test-requests/TR-1001/result/complete | C5: httpStatus = 400 response.code = "INVALID_RESULTFILE" database.updatedRows = 0 | D5: I2
A6: 4 | B6: conclusion = "CBC values within reference range" verifiedBy = "STF-HEAD-LAB-01" POST /api/v1/test-requests/TR-1001/result/complete | C6: httpStatus = 200 response.conclusion = "\"CBC values within reference range\"" database.updatedRows = 1 | D6: B4, V5
A7: 5 | B7: verifiedBy = "STF-DOC-01" POST /api/v1/test-requests/TR-1001/result/complete | C7: httpStatus = 400 response.code = "INVALID_VERIFIEDBY" database.updatedRows = 0 | D7: I5
A8: 6 | B8: queueTicket.status = "WAITING" POST /api/v1/test-requests/TR-1001/result/complete | C8: httpStatus = 409 response.code = "INVALID_QUEUE_STATUS" database.updatedRows = 0 | D8: I6

Sheet IT09-LabResult
A2: Feature | B2: IT09 - Laboratory result completion | R2: Passed
A3: Test requirement | B3: TestRequest -> TestResult -> QueueTicket -> PatientJourney | R3: Failed
A4: Number of TCs | B4: 6 | R4: Pending
A5: Testing Round | B5: Passed | C5: Failed | D5: Pending | E5: N/A | R5: N/A
A6: Round 1 | B6: =COUNTIF($F$12:$F$1000,B$5) -> 0 | C6: =COUNTIF($F$12:$F$1000,C$5) -> 0 | D6: =COUNTIF($F$12:$F$1000,D$5) -> 6 | E6: =COUNTIF($F$12:$F$1000,E$5) -> 0
A7: Round 2 | B7: =COUNTIF($I$12:$I$1000,B$5) -> 0 | C7: =COUNTIF($I$12:$I$1000,C$5) -> 0 | D7: =COUNTIF($I$12:$I$1000,D$5) -> 6 | E7: =COUNTIF($I$12:$I$1000,E$5) -> 0
A8: Round 3 | B8: =COUNTIF($L$12:$L$1000,B$5) -> 0 | C8: =COUNTIF($L$12:$L$1000,C$5) -> 0 | D8: =COUNTIF($L$12:$L$1000,D$5) -> 6 | E8: =COUNTIF($L$12:$L$1000,E$5) -> 0
A10: Test Case ID | B10: Test Case Description | C10: Test Case Procedure | D10: Expected Results | E10: Pre-conditions | F10: Round 1 | G10: Test date | H10: Tester | I10: Round 2 | J10: Test date | K10: Tester | L10: Round 3 | M10: Test date | N10: Tester | O10: Note
A11: Valid concrete input values
A12: IT09-001 | B12: Create or process laboratory result completion | C12: testRequest.status = "IN_PROGRESS" resultFile = "cbc-result.pdf" fileSize = 1048576 POST /api/v1/test-requests/TR-1001/result/complete | D12: httpStatus = 200 response.flow = "IT09" database.updatedRows = 1 | E12: testRequest.status = "IN_PROGRESS" resultFile = "cbc-result.pdf" | F12: Pending | I12: Pending | L12: Pending | O12: V1, V2, V3
A13: IT09-002 | B13: Reject invalid request status | C13: testRequest.status = "COMPLETED" resultFile = "cbc-result.pdf" POST /api/v1/test-requests/TR-1001/result/complete | D13: httpStatus = 404 response.code = "LABRESULT_NOT_FOUND" database.updatedRows = 0 | E13: testRequest.status = "COMPLETED" | F13: Pending | I13: Pending | L13: Pending | O13: I1
A14: Invalid concrete input values
A15: IT09-003 | B15: Reject invalid resultFile | C15: testRequest.status = "IN_PROGRESS" resultFile = "cbc-result.jpg" POST /api/v1/test-requests/TR-1001/result/complete | D15: httpStatus = 400 response.code = "INVALID_RESULTFILE" database.updatedRows = 0 | E15: testRequest.status = "IN_PROGRESS" | F15: Pending | I15: Pending | L15: Pending | O15: I2
A16: IT09-004 | B16: Accept boundary value for conclusion | C16: conclusion = "CBC values within reference range" verifiedBy = "STF-HEAD-LAB-01" POST /api/v1/test-requests/TR-1001/result/complete | D16: httpStatus = 200 response.conclusion = "\"CBC values within reference range\"" database.updatedRows = 1 | E16: testRequest.status = "IN_PROGRESS" | F16: Pending | I16: Pending | L16: Pending | O16: B4, V5
A17: Boundary and state values
A18: IT09-005 | B18: Reject invalid verifiedBy | C18: verifiedBy = "STF-DOC-01" POST /api/v1/test-requests/TR-1001/result/complete | D18: httpStatus = 400 response.code = "INVALID_VERIFIEDBY" database.updatedRows = 0 | E18: testRequest.status = "IN_PROGRESS" | F18: Pending | I18: Pending | L18: Pending | O18: I5
A19: IT09-006 | B19: Reject invalid queue status | C19: queueTicket.status = "WAITING" POST /api/v1/test-requests/TR-1001/result/complete | D19: httpStatus = 409 response.code = "INVALID_QUEUE_STATUS" database.updatedRows = 0 | E19: queueTicket.status = "WAITING" | F19: Pending | I19: Pending | L19: Pending | O19: I6

Sheet CA-IT02-LoginToken
A1: Test Condition Analysis
A2: Variable | B2: Valid Partition | C2: Tag | D2: Invalid Partition | E2: Tag | F2: Valid Boundary | G2: Tag | H2: Invalid Boundary | I2: Tag
A3: phone | B3: phone = "0944433222" | C3: V1 | D3: phone = "0900000000" | E3: I1 | F3: phone = "0944433222" | G3: B1 | H3: phone = "0900000000" | I3: IB1
A4: password | B4: password = "Clinic@123" | C4: V2 | D4: password = "Wrong@123" | E4: I2 | F4: password = "Clinic@123" | G4: B2 | H4: password = "Wrong@123" | I4: IB2
A5: account status | B5: account.isActive = true | C5: V3 | D5: account.isActive = false | E5: I3 | F5: account.isActive = true | G5: B3 | H5: account.isActive = false | I5: IB3
A6: refresh token | B6: token.type = "REFRESH" | C6: V4 | D6: token.type = "ACCESS" | E6: I4 | F6: token.type = "REFRESH" | G6: B4 | H6: token.type = "ACCESS" | I6: IB4
A7: token expiry | B7: token.expiresAt = "2026-08-13T10:00:00" | C7: V5 | D7: token.expiresAt = "2026-08-11T10:00:00" | E7: I5 | F7: token.expiresAt = "2026-08-13T10:00:00" | G7: B5 | H7: token.expiresAt = "2026-08-11T10:00:00" | I7: IB5
A8: authorization | B8: Authorization = "Bearer eyJ.valid" | C8: V6 | D8: Authorization = null | E8: I6 | F8: Authorization = "Bearer eyJ.valid" | G8: B6 | H8: Authorization = null | I8: IB6 | K8: TC | L8: VP1, VP2, VP3, VB1, VB3
A27: Notes: | B27: Every partition uses an explicit variable value. Tags are referenced by Test Design and Feature sheets.

Sheet TD-IT02-LoginToken
A1: Test Case Design
A2: Test Case | B2: Description | C2: Expected Outcome | D2: New Tag Covered
A3: 1 | B3: phone = "0944433222" password = "Clinic@123" POST /api/auth/login | C3: httpStatus = 200 response.accessToken != null response.refreshToken != null response.systemRole = "CUSTOMER" | D3: V1, V2, V3
A4: 2 | B4: phone = "0944433222" password = "Wrong@123" POST /api/auth/login | C4: httpStatus = 400 response.accessToken = null response.refreshToken = null | D4: I2
A5: 3 | B5: phone = "0944433222" password = "Clinic@123" POST /api/auth/login | C5: httpStatus = 400 response.code = "ACCOUNT_INACTIVE" response.accessToken = null | D5: I3
A6: 4 | B6: refreshToken = "eyJ.refresh.valid" POST /api/auth/refresh | C6: httpStatus = 200 response.accessToken != null response.refreshToken != null | D6: V4, V5
A7: 5 | B7: refreshToken = "eyJ.access.valid" POST /api/auth/refresh | C7: httpStatus = 400 response.code = "INVALID_TOKEN_TYPE" response.accessToken = null | D7: I4
A8: 6 | B8: Authorization = null GET /api/auth/me | C8: httpStatus = 401 response.code = "UNAUTHORIZED" response.accountId = null | D8: I6

Sheet IT02-LoginToken
A2: Feature | B2: IT02 - Login and token refresh | R2: Passed
A3: Test requirement | B3: Account -> Authentication -> JWT access/refresh | R3: Failed
A4: Number of TCs | B4: 6 | R4: Pending
A5: Testing Round | B5: Passed | C5: Failed | D5: Pending | E5: N/A | R5: N/A
A6: Round 1 | B6: =COUNTIF($F$12:$F$1000,B$5) -> 0 | C6: =COUNTIF($F$12:$F$1000,C$5) -> 0 | D6: =COUNTIF($F$12:$F$1000,D$5) -> 6 | E6: =COUNTIF($F$12:$F$1000,E$5) -> 0
A7: Round 2 | B7: =COUNTIF($I$12:$I$1000,B$5) -> 0 | C7: =COUNTIF($I$12:$I$1000,C$5) -> 0 | D7: =COUNTIF($I$12:$I$1000,D$5) -> 6 | E7: =COUNTIF($I$12:$I$1000,E$5) -> 0
A8: Round 3 | B8: =COUNTIF($L$12:$L$1000,B$5) -> 0 | C8: =COUNTIF($L$12:$L$1000,C$5) -> 0 | D8: =COUNTIF($L$12:$L$1000,D$5) -> 6 | E8: =COUNTIF($L$12:$L$1000,E$5) -> 0
A10: Test Case ID | B10: Test Case Description | C10: Test Case Procedure | D10: Expected Results | E10: Pre-conditions | F10: Round 1 | G10: Test date | H10: Tester | I10: Round 2 | J10: Test date | K10: Tester | L10: Round 3 | M10: Test date | N10: Tester | O10: Note
A11: Valid concrete input values
A12: IT02-001 | B12: Login with valid phone and password | C12: phone = "0944433222" password = "Clinic@123" POST /api/auth/login | D12: httpStatus = 200 response.accessToken != null response.refreshToken != null response.systemRole = "CUSTOMER" | E12: account.phone = "0944433222" account.password = "Clinic@123" account.isActive = true | F12: Pending | I12: Pending | L12: Pending | O12: V1, V2, V3
A13: IT02-002 | B13: Reject incorrect password | C13: phone = "0944433222" password = "Wrong@123" POST /api/auth/login | D13: httpStatus = 400 response.accessToken = null response.refreshToken = null | E13: account.phone = "0944433222" account.password = "Clinic@123" account.isActive = true | F13: Pending | I13: Pending | L13: Pending | O13: I2
A14: Invalid concrete input values
A15: IT02-003 | B15: Reject inactive account | C15: phone = "0944433222" password = "Clinic@123" POST /api/auth/login | D15: httpStatus = 400 response.code = "ACCOUNT_INACTIVE" response.accessToken = null | E15: account.phone = "0944433222" account.isActive = false | F15: Pending | I15: Pending | L15: Pending | O15: I3
A16: IT02-004 | B16: Refresh tokens with refresh token | C16: refreshToken = "eyJ.refresh.valid" POST /api/auth/refresh | D16: httpStatus = 200 response.accessToken != null response.refreshToken != null | E16: token.type = "REFRESH" token.revoked = false token.expiresAt = "2026-08-13T10:00:00" | F16: Pending | I16: Pending | L16: Pending | O16: V4, V5
A17: Boundary and state values
A18: IT02-005 | B18: Reject access token on refresh endpoint | C18: refreshToken = "eyJ.access.valid" POST /api/auth/refresh | D18: httpStatus = 400 response.code = "INVALID_TOKEN_TYPE" response.accessToken = null | E18: token.type = "ACCESS" | F18: Pending | I18: Pending | L18: Pending | O18: I4
A19: IT02-006 | B19: Reject request without bearer token | C19: Authorization = null GET /api/auth/me | D19: httpStatus = 401 response.code = "UNAUTHORIZED" response.accountId = null | E19: securityContext.authentication = null | F19: Pending | I19: Pending | L19: Pending | O19: I6

Sheet CA-IT03-Profile
A1: Test Condition Analysis
A2: Variable | B2: Valid Partition | C2: Tag | D2: Invalid Partition | E2: Tag | F2: Valid Boundary | G2: Tag | H2: Invalid Boundary | I2: Tag
A3: profile owner | B3: profile.accountId = "ACC-1001" | C3: V1 | D3: profile.accountId = "ACC-2002" | E3: I1 | F3: profile.accountId = "ACC-1001" | G3: B1 | H3: profile.accountId = "ACC-2002" | I3: IB1
A4: fullName | B4: fullName = "John Carter" | C4: V2 | D4: fullName = "" | E4: I2 | F4: fullName = "John Carter" | G4: B2 | H4: fullName = "" | I4: IB2
A5: phone | B5: phone = "0944433222" | C5: V3 | D5: phone = "123" | E5: I3 | F5: phone = "0944433222" | G5: B3 | H5: phone = "123" | I5: IB3
A6: email | B6: email = "john.carter@example.com" | C6: V4 | D6: email = "john.example.com" | E6: I4 | F6: email = "john.carter@example.com" | G6: B4 | H6: email = "john.example.com" | I6: IB4
A7: dateOfBirth | B7: dateOfBirth = "1998-05-20" | C7: V5 | D7: dateOfBirth = "2027-01-01" | E7: I5 | F7: dateOfBirth = "1998-05-20" | G7: B5 | H7: dateOfBirth = "2027-01-01" | I7: IB5
A8: insuranceCode | B8: insuranceCode = "BH1234567890123" | C8: V6 | D8: insuranceCode = "BH0000000000000" | E8: I6 | F8: insuranceCode = "BH1234567890123" | G8: B6 | H8: insuranceCode = "BH0000000000000" | I8: IB6 | K8: TC | L8: VP1, VP2, VP3, VB1, VB3
A27: Notes: | B27: Every partition uses an explicit variable value. Tags are referenced by Test Design and Feature sheets.

Sheet TD-IT03-Profile
A1: Test Case Design
A2: Test Case | B2: Description | C2: Expected Outcome | D2: New Tag Covered
A3: 1 | B3: profile.accountId = "ACC-1001" fullName = "John Carter" phone = "0944433222" PUT /api/v1/profiles/me | C3: httpStatus = 200 response.flow = "IT03" database.updatedRows = 1 | D3: V1, V2, V3
A4: 2 | B4: profile.accountId = "ACC-2002" fullName = "John Carter" PUT /api/v1/profiles/me | C4: httpStatus = 404 response.code = "PROFILE_NOT_FOUND" database.updatedRows = 0 | D4: I1
A5: 3 | B5: profile.accountId = "ACC-1001" fullName = "" PUT /api/v1/profiles/me | C5: httpStatus = 400 response.code = "INVALID_FULLNAME" database.updatedRows = 0 | D5: I2
A6: 4 | B6: email = "john.carter@example.com" dateOfBirth = "1998-05-20" PUT /api/v1/profiles/me | C6: httpStatus = 200 response.email = "\"john.carter@example.com\"" database.updatedRows = 1 | D6: B4, V5
A7: 5 | B7: dateOfBirth = "2027-01-01" PUT /api/v1/profiles/me | C7: httpStatus = 400 response.code = "INVALID_DATEOFBIRTH" database.updatedRows = 0 | D7: I5
A8: 6 | B8: insuranceCode = "BH0000000000000" PUT /api/v1/profiles/me | C8: httpStatus = 409 response.code = "INVALID_INSURANCECODE" database.updatedRows = 0 | D8: I6

Sheet IT03-Profile
A2: Feature | B2: IT03 - Customer profile management | R2: Passed
A3: Test requirement | B3: Account -> Profile -> Insurance lookup | R3: Failed
A4: Number of TCs | B4: 6 | R4: Pending
A5: Testing Round | B5: Passed | C5: Failed | D5: Pending | E5: N/A | R5: N/A
A6: Round 1 | B6: =COUNTIF($F$12:$F$1000,B$5) -> 0 | C6: =COUNTIF($F$12:$F$1000,C$5) -> 0 | D6: =COUNTIF($F$12:$F$1000,D$5) -> 6 | E6: =COUNTIF($F$12:$F$1000,E$5) -> 0
A7: Round 2 | B7: =COUNTIF($I$12:$I$1000,B$5) -> 0 | C7: =COUNTIF($I$12:$I$1000,C$5) -> 0 | D7: =COUNTIF($I$12:$I$1000,D$5) -> 6 | E7: =COUNTIF($I$12:$I$1000,E$5) -> 0
A8: Round 3 | B8: =COUNTIF($L$12:$L$1000,B$5) -> 0 | C8: =COUNTIF($L$12:$L$1000,C$5) -> 0 | D8: =COUNTIF($L$12:$L$1000,D$5) -> 6 | E8: =COUNTIF($L$12:$L$1000,E$5) -> 0
A10: Test Case ID | B10: Test Case Description | C10: Test Case Procedure | D10: Expected Results | E10: Pre-conditions | F10: Round 1 | G10: Test date | H10: Tester | I10: Round 2 | J10: Test date | K10: Tester | L10: Round 3 | M10: Test date | N10: Tester | O10: Note
A11: Valid concrete input values
A12: IT03-001 | B12: Create or process customer profile management | C12: profile.accountId = "ACC-1001" fullName = "John Carter" phone = "0944433222" PUT /api/v1/profiles/me | D12: httpStatus = 200 response.flow = "IT03" database.updatedRows = 1 | E12: profile.accountId = "ACC-1001" fullName = "John Carter" | F12: Pending | I12: Pending | L12: Pending | O12: V1, V2, V3
A13: IT03-002 | B13: Reject invalid profile owner | C13: profile.accountId = "ACC-2002" fullName = "John Carter" PUT /api/v1/profiles/me | D13: httpStatus = 404 response.code = "PROFILE_NOT_FOUND" database.updatedRows = 0 | E13: profile.accountId = "ACC-2002" | F13: Pending | I13: Pending | L13: Pending | O13: I1
A14: Invalid concrete input values
A15: IT03-003 | B15: Reject invalid fullName | C15: profile.accountId = "ACC-1001" fullName = "" PUT /api/v1/profiles/me | D15: httpStatus = 400 response.code = "INVALID_FULLNAME" database.updatedRows = 0 | E15: profile.accountId = "ACC-1001" | F15: Pending | I15: Pending | L15: Pending | O15: I2
A16: IT03-004 | B16: Accept boundary value for email | C16: email = "john.carter@example.com" dateOfBirth = "1998-05-20" PUT /api/v1/profiles/me | D16: httpStatus = 200 response.email = "\"john.carter@example.com\"" database.updatedRows = 1 | E16: profile.accountId = "ACC-1001" | F16: Pending | I16: Pending | L16: Pending | O16: B4, V5
A17: Boundary and state values
A18: IT03-005 | B18: Reject invalid dateOfBirth | C18: dateOfBirth = "2027-01-01" PUT /api/v1/profiles/me | D18: httpStatus = 400 response.code = "INVALID_DATEOFBIRTH" database.updatedRows = 0 | E18: profile.accountId = "ACC-1001" | F18: Pending | I18: Pending | L18: Pending | O18: I5
A19: IT03-006 | B19: Reject invalid insuranceCode | C19: insuranceCode = "BH0000000000000" PUT /api/v1/profiles/me | D19: httpStatus = 409 response.code = "INVALID_INSURANCECODE" database.updatedRows = 0 | E19: insuranceCode = "BH0000000000000" | F19: Pending | I19: Pending | L19: Pending | O19: I6

Sheet CA-IT05-PaymentQueue
A1: Test Condition Analysis
A2: Variable | B2: Valid Partition | C2: Tag | D2: Invalid Partition | E2: Tag | F2: Valid Boundary | G2: Tag | H2: Invalid Boundary | I2: Tag
A3: invoice status | B3: invoice.status = "PENDING" | C3: V1 | D3: invoice.status = "PAID" | E3: I1 | F3: invoice.status = "PENDING" | G3: B1 | H3: invoice.status = "PAID" | I3: IB1
A4: amount | B4: amount = 500000 | C4: V2 | D4: amount = 499999 | E4: I2 | F4: amount = 500000 | G4: B2 | H4: amount = 499999 | I4: IB2
A5: paymentMethod | B5: paymentMethod = "CASH" | C5: V3 | D5: paymentMethod = "BITCOIN" | E5: I3 | F5: paymentMethod = "CASH" | G5: B3 | H5: paymentMethod = "BITCOIN" | I5: IB3
A6: invoice item count | B6: invoiceItem.count = 1 | C6: V4 | D6: invoiceItem.count = 0 | E6: I4 | F6: invoiceItem.count = 1 | G6: B4 | H6: invoiceItem.count = 0 | I6: IB4
A7: transaction status | B7: transaction.status = "PENDING" | C7: V5 | D7: transaction.status = "SUCCESS" | E7: I5 | F7: transaction.status = "PENDING" | G7: B5 | H7: transaction.status = "SUCCESS" | I7: IB5
A8: queue count | B8: queueTicket.count = 0 | C8: V6 | D8: queueTicket.count = 1 | E8: I6 | F8: queueTicket.count = 0 | G8: B6 | H8: queueTicket.count = 1 | I8: IB6 | K8: TC | L8: VP1, VP2, VP3, VB1, VB3
A27: Notes: | B27: Every partition uses an explicit variable value. Tags are referenced by Test Design and Feature sheets.

Sheet TD-IT05-PaymentQueue
A1: Test Case Design
A2: Test Case | B2: Description | C2: Expected Outcome | D2: New Tag Covered
A3: 1 | B3: invoice.status = "PENDING" amount = 500000 paymentMethod = "CASH" POST /api/v1/invoices/INV-1001/pay | C3: httpStatus = 200 response.flow = "IT05" database.updatedRows = 1 | D3: V1, V2, V3
A4: 2 | B4: invoice.status = "PAID" amount = 500000 POST /api/v1/invoices/INV-1001/pay | C4: httpStatus = 404 response.code = "PAYMENTQUEUE_NOT_FOUND" database.updatedRows = 0 | D4: I1
A5: 3 | B5: invoice.status = "PENDING" amount = 499999 POST /api/v1/invoices/INV-1001/pay | C5: httpStatus = 400 response.code = "INVALID_AMOUNT" database.updatedRows = 0 | D5: I2
A6: 4 | B6: invoiceItem.count = 1 transaction.status = "PENDING" POST /api/v1/invoices/INV-1001/pay | C6: httpStatus = 200 response.invoiceitemcount = "1" database.updatedRows = 1 | D6: B4, V5
A7: 5 | B7: transaction.status = "SUCCESS" POST /api/v1/invoices/INV-1001/pay | C7: httpStatus = 400 response.code = "INVALID_TRANSACTION_STATUS" database.updatedRows = 0 | D7: I5
A8: 6 | B8: queueTicket.count = 1 POST /api/v1/invoices/INV-1001/pay | C8: httpStatus = 409 response.code = "INVALID_QUEUE_COUNT" database.updatedRows = 0 | D8: I6

Sheet IT05-PaymentQueue
A2: Feature | B2: IT05 - Invoice payment and queue creation | R2: Passed
A3: Test requirement | B3: Invoice -> Transaction -> QueueTicket | R3: Failed
A4: Number of TCs | B4: 6 | R4: Pending
A5: Testing Round | B5: Passed | C5: Failed | D5: Pending | E5: N/A | R5: N/A
A6: Round 1 | B6: =COUNTIF($F$12:$F$1000,B$5) -> 0 | C6: =COUNTIF($F$12:$F$1000,C$5) -> 0 | D6: =COUNTIF($F$12:$F$1000,D$5) -> 6 | E6: =COUNTIF($F$12:$F$1000,E$5) -> 0
A7: Round 2 | B7: =COUNTIF($I$12:$I$1000,B$5) -> 0 | C7: =COUNTIF($I$12:$I$1000,C$5) -> 0 | D7: =COUNTIF($I$12:$I$1000,D$5) -> 6 | E7: =COUNTIF($I$12:$I$1000,E$5) -> 0
A8: Round 3 | B8: =COUNTIF($L$12:$L$1000,B$5) -> 0 | C8: =COUNTIF($L$12:$L$1000,C$5) -> 0 | D8: =COUNTIF($L$12:$L$1000,D$5) -> 6 | E8: =COUNTIF($L$12:$L$1000,E$5) -> 0
A10: Test Case ID | B10: Test Case Description | C10: Test Case Procedure | D10: Expected Results | E10: Pre-conditions | F10: Round 1 | G10: Test date | H10: Tester | I10: Round 2 | J10: Test date | K10: Tester | L10: Round 3 | M10: Test date | N10: Tester | O10: Note
A11: Valid concrete input values
A12: IT05-001 | B12: Create or process invoice payment and queue creation | C12: invoice.status = "PENDING" amount = 500000 paymentMethod = "CASH" POST /api/v1/invoices/INV-1001/pay | D12: httpStatus = 200 response.flow = "IT05" database.updatedRows = 1 | E12: invoice.status = "PENDING" amount = 500000 | F12: Pending | I12: Pending | L12: Pending | O12: V1, V2, V3
A13: IT05-002 | B13: Reject invalid invoice status | C13: invoice.status = "PAID" amount = 500000 POST /api/v1/invoices/INV-1001/pay | D13: httpStatus = 404 response.code = "PAYMENTQUEUE_NOT_FOUND" database.updatedRows = 0 | E13: invoice.status = "PAID" | F13: Pending | I13: Pending | L13: Pending | O13: I1
A14: Invalid concrete input values
A15: IT05-003 | B15: Reject invalid amount | C15: invoice.status = "PENDING" amount = 499999 POST /api/v1/invoices/INV-1001/pay | D15: httpStatus = 400 response.code = "INVALID_AMOUNT" database.updatedRows = 0 | E15: invoice.status = "PENDING" | F15: Pending | I15: Pending | L15: Pending | O15: I2
A16: IT05-004 | B16: Accept boundary value for invoice item count | C16: invoiceItem.count = 1 transaction.status = "PENDING" POST /api/v1/invoices/INV-1001/pay | D16: httpStatus = 200 response.invoiceitemcount = "1" database.updatedRows = 1 | E16: invoice.status = "PENDING" | F16: Pending | I16: Pending | L16: Pending | O16: B4, V5
A17: Boundary and state values
A18: IT05-005 | B18: Reject invalid transaction status | C18: transaction.status = "SUCCESS" POST /api/v1/invoices/INV-1001/pay | D18: httpStatus = 400 response.code = "INVALID_TRANSACTION_STATUS" database.updatedRows = 0 | E18: invoice.status = "PENDING" | F18: Pending | I18: Pending | L18: Pending | O18: I5
A19: IT05-006 | B19: Reject invalid queue count | C19: queueTicket.count = 1 POST /api/v1/invoices/INV-1001/pay | D19: httpStatus = 409 response.code = "INVALID_QUEUE_COUNT" database.updatedRows = 0 | E19: queueTicket.count = 1 | F19: Pending | I19: Pending | L19: Pending | O19: I6

Sheet CA-IT06-QueueExam
A1: Test Condition Analysis
A2: Variable | B2: Valid Partition | C2: Tag | D2: Invalid Partition | E2: Tag | F2: Valid Boundary | G2: Tag | H2: Invalid Boundary | I2: Tag
A3: queue status | B3: queueTicket.status = "WAITING" | C3: V1 | D3: queueTicket.status = "DONE" | E3: I1 | F3: queueTicket.status = "WAITING" | G3: B1 | H3: queueTicket.status = "DONE" | I3: IB1
A4: department | B4: departmentId = "DEP-GENERAL" | C4: V2 | D4: departmentId = "DEP-LAB" | E4: I2 | F4: departmentId = "DEP-GENERAL" | G4: B2 | H4: departmentId = "DEP-LAB" | I4: IB2
A5: staff role | B5: staff.systemRole = "DOCTOR" | C5: V3 | D5: staff.systemRole = "CUSTOMER" | E5: I3 | F5: staff.systemRole = "DOCTOR" | G5: B3 | H5: staff.systemRole = "CUSTOMER" | I5: IB3
A6: visit status | B6: customerVisit.status = "CHECKED_IN" | C6: V4 | D6: customerVisit.status = "COMPLETED" | E6: I4 | F6: customerVisit.status = "CHECKED_IN" | G6: B4 | H6: customerVisit.status = "COMPLETED" | I6: IB4
A7: temperature | B7: temperature = 36.8 | C7: V5 | D7: temperature = 50.0 | E7: I5 | F7: temperature = 36.8 | G7: B5 | H7: temperature = 50.0 | I7: IB5
A8: medical record count | B8: medicalRecord.count = 0 | C8: V6 | D8: medicalRecord.count = 1 | E8: I6 | F8: medicalRecord.count = 0 | G8: B6 | H8: medicalRecord.count = 1 | I8: IB6 | K8: TC | L8: VP1, VP2, VP3, VB1, VB3
A27: Notes: | B27: Every partition uses an explicit variable value. Tags are referenced by Test Design and Feature sheets.

Sheet TD-IT06-QueueExam
A1: Test Case Design
A2: Test Case | B2: Description | C2: Expected Outcome | D2: New Tag Covered
A3: 1 | B3: queueTicket.status = "WAITING" departmentId = "DEP-GENERAL" staff.systemRole = "DOCTOR" POST /api/v1/queue-tickets/QUE-1001/call | C3: httpStatus = 200 response.flow = "IT06" database.updatedRows = 1 | D3: V1, V2, V3
A4: 2 | B4: queueTicket.status = "DONE" departmentId = "DEP-GENERAL" POST /api/v1/queue-tickets/QUE-1001/call | C4: httpStatus = 404 response.code = "QUEUEEXAM_NOT_FOUND" database.updatedRows = 0 | D4: I1
A5: 3 | B5: queueTicket.status = "WAITING" departmentId = "DEP-LAB" POST /api/v1/queue-tickets/QUE-1001/call | C5: httpStatus = 400 response.code = "INVALID_DEPARTMENT" database.updatedRows = 0 | D5: I2
A6: 4 | B6: customerVisit.status = "CHECKED_IN" temperature = 36.8 POST /api/v1/queue-tickets/QUE-1001/call | C6: httpStatus = 200 response.visitstatus = "\"CHECKED_IN\"" database.updatedRows = 1 | D6: B4, V5
A7: 5 | B7: temperature = 50.0 POST /api/v1/queue-tickets/QUE-1001/call | C7: httpStatus = 400 response.code = "INVALID_TEMPERATURE" database.updatedRows = 0 | D7: I5
A8: 6 | B8: medicalRecord.count = 1 POST /api/v1/queue-tickets/QUE-1001/call | C8: httpStatus = 409 response.code = "INVALID_MEDICAL_RECORD_COUNT" database.updatedRows = 0 | D8: I6

Sheet IT06-QueueExam
A2: Feature | B2: IT06 - Queue handling and examination start | R2: Passed
A3: Test requirement | B3: QueueTicket -> CustomerVisit -> VitalSigns -> MedicalRecord | R3: Failed
A4: Number of TCs | B4: 6 | R4: Pending
A5: Testing Round | B5: Passed | C5: Failed | D5: Pending | E5: N/A | R5: N/A
A6: Round 1 | B6: =COUNTIF($F$12:$F$1000,B$5) -> 0 | C6: =COUNTIF($F$12:$F$1000,C$5) -> 0 | D6: =COUNTIF($F$12:$F$1000,D$5) -> 6 | E6: =COUNTIF($F$12:$F$1000,E$5) -> 0
A7: Round 2 | B7: =COUNTIF($I$12:$I$1000,B$5) -> 0 | C7: =COUNTIF($I$12:$I$1000,C$5) -> 0 | D7: =COUNTIF($I$12:$I$1000,D$5) -> 6 | E7: =COUNTIF($I$12:$I$1000,E$5) -> 0
A8: Round 3 | B8: =COUNTIF($L$12:$L$1000,B$5) -> 0 | C8: =COUNTIF($L$12:$L$1000,C$5) -> 0 | D8: =COUNTIF($L$12:$L$1000,D$5) -> 6 | E8: =COUNTIF($L$12:$L$1000,E$5) -> 0
A10: Test Case ID | B10: Test Case Description | C10: Test Case Procedure | D10: Expected Results | E10: Pre-conditions | F10: Round 1 | G10: Test date | H10: Tester | I10: Round 2 | J10: Test date | K10: Tester | L10: Round 3 | M10: Test date | N10: Tester | O10: Note
A11: Valid concrete input values
A12: IT06-001 | B12: Create or process queue handling and examination start | C12: queueTicket.status = "WAITING" departmentId = "DEP-GENERAL" staff.systemRole = "DOCTOR" POST /api/v1/queue-tickets/QUE-1001/call | D12: httpStatus = 200 response.flow = "IT06" database.updatedRows = 1 | E12: queueTicket.status = "WAITING" departmentId = "DEP-GENERAL" | F12: Pending | I12: Pending | L12: Pending | O12: V1, V2, V3
A13: IT06-002 | B13: Reject invalid queue status | C13: queueTicket.status = "DONE" departmentId = "DEP-GENERAL" POST /api/v1/queue-tickets/QUE-1001/call | D13: httpStatus = 404 response.code = "QUEUEEXAM_NOT_FOUND" database.updatedRows = 0 | E13: queueTicket.status = "DONE" | F13: Pending | I13: Pending | L13: Pending | O13: I1
A14: Invalid concrete input values
A15: IT06-003 | B15: Reject invalid department | C15: queueTicket.status = "WAITING" departmentId = "DEP-LAB" POST /api/v1/queue-tickets/QUE-1001/call | D15: httpStatus = 400 response.code = "INVALID_DEPARTMENT" database.updatedRows = 0 | E15: queueTicket.status = "WAITING" | F15: Pending | I15: Pending | L15: Pending | O15: I2
A16: IT06-004 | B16: Accept boundary value for visit status | C16: customerVisit.status = "CHECKED_IN" temperature = 36.8 POST /api/v1/queue-tickets/QUE-1001/call | D16: httpStatus = 200 response.visitstatus = "\"CHECKED_IN\"" database.updatedRows = 1 | E16: queueTicket.status = "WAITING" | F16: Pending | I16: Pending | L16: Pending | O16: B4, V5
A17: Boundary and state values
A18: IT06-005 | B18: Reject invalid temperature | C18: temperature = 50.0 POST /api/v1/queue-tickets/QUE-1001/call | D18: httpStatus = 400 response.code = "INVALID_TEMPERATURE" database.updatedRows = 0 | E18: queueTicket.status = "WAITING" | F18: Pending | I18: Pending | L18: Pending | O18: I5
A19: IT06-006 | B19: Reject invalid medical record count | C19: medicalRecord.count = 1 POST /api/v1/queue-tickets/QUE-1001/call | D19: httpStatus = 409 response.code = "INVALID_MEDICAL_RECORD_COUNT" database.updatedRows = 0 | E19: medicalRecord.count = 1 | F19: Pending | I19: Pending | L19: Pending | O19: I6

Sheet CA-IT07-Examination
A1: Test Condition Analysis
A2: Variable | B2: Valid Partition | C2: Tag | D2: Invalid Partition | E2: Tag | F2: Valid Boundary | G2: Tag | H2: Invalid Boundary | I2: Tag
A3: record status | B3: medicalRecord.status = "IN_PROGRESS" | C3: V1 | D3: medicalRecord.status = "COMPLETED" | E3: I1 | F3: medicalRecord.status = "IN_PROGRESS" | G3: B1 | H3: medicalRecord.status = "COMPLETED" | I3: IB1
A4: doctorId | B4: doctorId = "STF-DOC-01" | C4: V2 | D4: doctorId = "STF-DOC-99" | E4: I2 | F4: doctorId = "STF-DOC-01" | G4: B2 | H4: doctorId = "STF-DOC-99" | I4: IB2
A5: icd10Code | B5: icd10Code = "J00" | C5: V3 | D5: icd10Code = "ZZZ" | E5: I3 | F5: icd10Code = "J00" | G5: B3 | H5: icd10Code = "ZZZ" | I5: IB3
A6: medicineId | B6: medicineId = "MED-001" | C6: V4 | D6: medicineId = "MED-999" | E6: I4 | F6: medicineId = "MED-001" | G6: B4 | H6: medicineId = "MED-999" | I6: IB4
A7: quantity | B7: quantity = 10 | C7: V5 | D7: quantity = 0 | E7: I5 | F7: quantity = 10 | G7: B5 | H7: quantity = 0 | I7: IB5
A8: dose | B8: dose = "1 tablet twice daily" | C8: V6 | D8: dose = "" | E8: I6 | F8: dose = "1 tablet twice daily" | G8: B6 | H8: dose = "" | I8: IB6 | K8: TC | L8: VP1, VP2, VP3, VB1, VB3
A27: Notes: | B27: Every partition uses an explicit variable value. Tags are referenced by Test Design and Feature sheets.

Sheet TD-IT07-Examination
A1: Test Case Design
A2: Test Case | B2: Description | C2: Expected Outcome | D2: New Tag Covered
A3: 1 | B3: medicalRecord.status = "IN_PROGRESS" doctorId = "STF-DOC-01" icd10Code = "J00" PUT /api/doctor/examinations/MR-1001 | C3: httpStatus = 200 response.flow = "IT07" database.updatedRows = 1 | D3: V1, V2, V3
A4: 2 | B4: medicalRecord.status = "COMPLETED" doctorId = "STF-DOC-01" PUT /api/doctor/examinations/MR-1001 | C4: httpStatus = 404 response.code = "EXAMINATION_NOT_FOUND" database.updatedRows = 0 | D4: I1
A5: 3 | B5: medicalRecord.status = "IN_PROGRESS" doctorId = "STF-DOC-99" PUT /api/doctor/examinations/MR-1001 | C5: httpStatus = 400 response.code = "INVALID_DOCTORID" database.updatedRows = 0 | D5: I2
A6: 4 | B6: medicineId = "MED-001" quantity = 10 PUT /api/doctor/examinations/MR-1001 | C6: httpStatus = 200 response.medicineId = "\"MED-001\"" database.updatedRows = 1 | D6: B4, V5
A7: 5 | B7: quantity = 0 PUT /api/doctor/examinations/MR-1001 | C7: httpStatus = 400 response.code = "INVALID_QUANTITY" database.updatedRows = 0 | D7: I5
A8: 6 | B8: dose = "" PUT /api/doctor/examinations/MR-1001 | C8: httpStatus = 409 response.code = "INVALID_DOSE" database.updatedRows = 0 | D8: I6

Sheet IT07-Examination
A2: Feature | B2: IT07 - Diagnosis and prescription | R2: Passed
A3: Test requirement | B3: Visit -> MedicalRecord -> ICD-10 -> Prescription | R3: Failed
A4: Number of TCs | B4: 6 | R4: Pending
A5: Testing Round | B5: Passed | C5: Failed | D5: Pending | E5: N/A | R5: N/A
A6: Round 1 | B6: =COUNTIF($F$12:$F$1000,B$5) -> 0 | C6: =COUNTIF($F$12:$F$1000,C$5) -> 0 | D6: =COUNTIF($F$12:$F$1000,D$5) -> 6 | E6: =COUNTIF($F$12:$F$1000,E$5) -> 0
A7: Round 2 | B7: =COUNTIF($I$12:$I$1000,B$5) -> 0 | C7: =COUNTIF($I$12:$I$1000,C$5) -> 0 | D7: =COUNTIF($I$12:$I$1000,D$5) -> 6 | E7: =COUNTIF($I$12:$I$1000,E$5) -> 0
A8: Round 3 | B8: =COUNTIF($L$12:$L$1000,B$5) -> 0 | C8: =COUNTIF($L$12:$L$1000,C$5) -> 0 | D8: =COUNTIF($L$12:$L$1000,D$5) -> 6 | E8: =COUNTIF($L$12:$L$1000,E$5) -> 0
A10: Test Case ID | B10: Test Case Description | C10: Test Case Procedure | D10: Expected Results | E10: Pre-conditions | F10: Round 1 | G10: Test date | H10: Tester | I10: Round 2 | J10: Test date | K10: Tester | L10: Round 3 | M10: Test date | N10: Tester | O10: Note
A11: Valid concrete input values
A12: IT07-001 | B12: Create or process diagnosis and prescription | C12: medicalRecord.status = "IN_PROGRESS" doctorId = "STF-DOC-01" icd10Code = "J00" PUT /api/doctor/examinations/MR-1001 | D12: httpStatus = 200 response.flow = "IT07" database.updatedRows = 1 | E12: medicalRecord.status = "IN_PROGRESS" doctorId = "STF-DOC-01" | F12: Pending | I12: Pending | L12: Pending | O12: V1, V2, V3
A13: IT07-002 | B13: Reject invalid record status | C13: medicalRecord.status = "COMPLETED" doctorId = "STF-DOC-01" PUT /api/doctor/examinations/MR-1001 | D13: httpStatus = 404 response.code = "EXAMINATION_NOT_FOUND" database.updatedRows = 0 | E13: medicalRecord.status = "COMPLETED" | F13: Pending | I13: Pending | L13: Pending | O13: I1
A14: Invalid concrete input values
A15: IT07-003 | B15: Reject invalid doctorId | C15: medicalRecord.status = "IN_PROGRESS" doctorId = "STF-DOC-99" PUT /api/doctor/examinations/MR-1001 | D15: httpStatus = 400 response.code = "INVALID_DOCTORID" database.updatedRows = 0 | E15: medicalRecord.status = "IN_PROGRESS" | F15: Pending | I15: Pending | L15: Pending | O15: I2
A16: IT07-004 | B16: Accept boundary value for medicineId | C16: medicineId = "MED-001" quantity = 10 PUT /api/doctor/examinations/MR-1001 | D16: httpStatus = 200 response.medicineId = "\"MED-001\"" database.updatedRows = 1 | E16: medicalRecord.status = "IN_PROGRESS" | F16: Pending | I16: Pending | L16: Pending | O16: B4, V5
A17: Boundary and state values
A18: IT07-005 | B18: Reject invalid quantity | C18: quantity = 0 PUT /api/doctor/examinations/MR-1001 | D18: httpStatus = 400 response.code = "INVALID_QUANTITY" database.updatedRows = 0 | E18: medicalRecord.status = "IN_PROGRESS" | F18: Pending | I18: Pending | L18: Pending | O18: I5
A19: IT07-006 | B19: Reject invalid dose | C19: dose = "" PUT /api/doctor/examinations/MR-1001 | D19: httpStatus = 409 response.code = "INVALID_DOSE" database.updatedRows = 0 | E19: dose = "" | F19: Pending | I19: Pending | L19: Pending | O19: I6

Sheet CA-IT08-TestOrder
A1: Test Condition Analysis
A2: Variable | B2: Valid Partition | C2: Tag | D2: Invalid Partition | E2: Tag | F2: Valid Boundary | G2: Tag | H2: Invalid Boundary | I2: Tag
A3: medicalRecordId | B3: medicalRecordId = "MR-1001" | C3: V1 | D3: medicalRecordId = "MR-9999" | E3: I1 | F3: medicalRecordId = "MR-1001" | G3: B1 | H3: medicalRecordId = "MR-9999" | I3: IB1
A4: serviceId | B4: serviceId = "SRV-LAB-CBC" | C4: V2 | D4: serviceId = "SRV-UNKNOWN" | E4: I2 | F4: serviceId = "SRV-LAB-CBC" | G4: B2 | H4: serviceId = "SRV-UNKNOWN" | I4: IB2
A5: department status | B5: department.status = "ACTIVE" | C5: V3 | D5: department.status = "MAINTENANCE" | E5: I3 | F5: department.status = "ACTIVE" | G5: B3 | H5: department.status = "MAINTENANCE" | I5: IB3
A6: request count | B6: sameServiceRequest.count = 0 | C6: V4 | D6: sameServiceRequest.count = 1 | E6: I4 | F6: sameServiceRequest.count = 0 | G6: B4 | H6: sameServiceRequest.count = 1 | I6: IB4
A7: serviceIds | B7: serviceIds = ["SRV-LAB-CBC"] | C7: V5 | D7: serviceIds = [] | E7: I5 | F7: serviceIds = ["SRV-LAB-CBC"] | G7: B5 | H7: serviceIds = [] | I7: IB5
A8: queue status | B8: queueTicket.status = "WAITING" | C8: V6 | D8: queueTicket.status = "BLOCKED" | E8: I6 | F8: queueTicket.status = "WAITING" | G8: B6 | H8: queueTicket.status = "BLOCKED" | I8: IB6 | K8: TC | L8: VP1, VP2, VP3, VB1, VB3
A27: Notes: | B27: Every partition uses an explicit variable value. Tags are referenced by Test Design and Feature sheets.

Sheet TD-IT08-TestOrder
A1: Test Case Design
A2: Test Case | B2: Description | C2: Expected Outcome | D2: New Tag Covered
A3: 1 | B3: medicalRecordId = "MR-1001" serviceId = "SRV-LAB-CBC" department.status = "ACTIVE" POST /api/v1/test-requests | C3: httpStatus = 200 response.flow = "IT08" database.updatedRows = 1 | D3: V1, V2, V3
A4: 2 | B4: medicalRecordId = "MR-9999" serviceId = "SRV-LAB-CBC" POST /api/v1/test-requests | C4: httpStatus = 404 response.code = "TESTORDER_NOT_FOUND" database.updatedRows = 0 | D4: I1
A5: 3 | B5: medicalRecordId = "MR-1001" serviceId = "SRV-UNKNOWN" POST /api/v1/test-requests | C5: httpStatus = 400 response.code = "INVALID_SERVICEID" database.updatedRows = 0 | D5: I2
A6: 4 | B6: sameServiceRequest.count = 0 serviceIds = ["SRV-LAB-CBC"] POST /api/v1/test-requests | C6: httpStatus = 200 response.requestcount = "0" database.updatedRows = 1 | D6: B4, V5
A7: 5 | B7: serviceIds = [] POST /api/v1/test-requests | C7: httpStatus = 400 response.code = "INVALID_SERVICEIDS" database.updatedRows = 0 | D7: I5
A8: 6 | B8: queueTicket.status = "BLOCKED" POST /api/v1/test-requests | C8: httpStatus = 409 response.code = "INVALID_QUEUE_STATUS" database.updatedRows = 0 | D8: I6

Sheet IT08-TestOrder
A2: Feature | B2: IT08 - Clinical test ordering | R2: Passed
A3: Test requirement | B3: MedicalRecord -> TestRequest -> Department -> QueueTicket | R3: Failed
A4: Number of TCs | B4: 6 | R4: Pending
A5: Testing Round | B5: Passed | C5: Failed | D5: Pending | E5: N/A | R5: N/A
A6: Round 1 | B6: =COUNTIF($F$12:$F$1000,B$5) -> 0 | C6: =COUNTIF($F$12:$F$1000,C$5) -> 0 | D6: =COUNTIF($F$12:$F$1000,D$5) -> 6 | E6: =COUNTIF($F$12:$F$1000,E$5) -> 0
A7: Round 2 | B7: =COUNTIF($I$12:$I$1000,B$5) -> 0 | C7: =COUNTIF($I$12:$I$1000,C$5) -> 0 | D7: =COUNTIF($I$12:$I$1000,D$5) -> 6 | E7: =COUNTIF($I$12:$I$1000,E$5) -> 0
A8: Round 3 | B8: =COUNTIF($L$12:$L$1000,B$5) -> 0 | C8: =COUNTIF($L$12:$L$1000,C$5) -> 0 | D8: =COUNTIF($L$12:$L$1000,D$5) -> 6 | E8: =COUNTIF($L$12:$L$1000,E$5) -> 0
A10: Test Case ID | B10: Test Case Description | C10: Test Case Procedure | D10: Expected Results | E10: Pre-conditions | F10: Round 1 | G10: Test date | H10: Tester | I10: Round 2 | J10: Test date | K10: Tester | L10: Round 3 | M10: Test date | N10: Tester | O10: Note
A11: Valid concrete input values
A12: IT08-001 | B12: Create or process clinical test ordering | C12: medicalRecordId = "MR-1001" serviceId = "SRV-LAB-CBC" department.status = "ACTIVE" POST /api/v1/test-requests | D12: httpStatus = 200 response.flow = "IT08" database.updatedRows = 1 | E12: medicalRecordId = "MR-1001" serviceId = "SRV-LAB-CBC" | F12: Pending | I12: Pending | L12: Pending | O12: V1, V2, V3
